[2025-09-04T16:05:21.500+0000] {local_task_job_runner.py:120} INFO - ::group::Pre task execution logs
[2025-09-04T16:05:21.549+0000] {taskinstance.py:2076} INFO - Dependencies all met for dep_context=non-requeueable deps ti=<TaskInstance: dbt_run_models.run_dbt_models scheduled__2025-09-04T15:00:00+00:00 [queued]>
[2025-09-04T16:05:21.572+0000] {taskinstance.py:2076} INFO - Dependencies all met for dep_context=requeueable deps ti=<TaskInstance: dbt_run_models.run_dbt_models scheduled__2025-09-04T15:00:00+00:00 [queued]>
[2025-09-04T16:05:21.573+0000] {taskinstance.py:2306} INFO - Starting attempt 2 of 2
[2025-09-04T16:05:21.622+0000] {taskinstance.py:2330} INFO - Executing <Task(BashOperator): run_dbt_models> on 2025-09-04 15:00:00+00:00
[2025-09-04T16:05:21.630+0000] {warnings.py:112} WARNING - /home/airflow/.local/lib/python3.12/site-packages/airflow/task/task_runner/standard_task_runner.py:62: DeprecationWarning: This process (pid=546) is multi-threaded, use of fork() may lead to deadlocks in the child.
  pid = os.fork()

[2025-09-04T16:05:21.631+0000] {standard_task_runner.py:64} INFO - Started process 547 to run task
[2025-09-04T16:05:21.634+0000] {standard_task_runner.py:90} INFO - Running: ['airflow', 'tasks', 'run', 'dbt_run_models', 'run_dbt_models', 'scheduled__2025-09-04T15:00:00+00:00', '--job-id', '1014', '--raw', '--subdir', 'DAGS_FOLDER/dbt_dag.py', '--cfg-path', '/tmp/tmplod9nzsi']
[2025-09-04T16:05:21.634+0000] {standard_task_runner.py:91} INFO - Job 1014: Subtask run_dbt_models
[2025-09-04T16:05:21.664+0000] {warnings.py:112} WARNING - /home/airflow/.local/lib/python3.12/site-packages/airflow/settings.py:195: DeprecationWarning: The sql_alchemy_conn option in [core] has been moved to the sql_alchemy_conn option in [database] - the old setting has been used, but please update your config.
  SQL_ALCHEMY_CONN = conf.get("database", "SQL_ALCHEMY_CONN")

[2025-09-04T16:05:21.744+0000] {task_command.py:426} INFO - Running <TaskInstance: dbt_run_models.run_dbt_models scheduled__2025-09-04T15:00:00+00:00 [running]> on host b5ea13053d47
[2025-09-04T16:05:21.971+0000] {taskinstance.py:2648} INFO - Exporting env vars: AIRFLOW_CTX_DAG_OWNER='airflow' AIRFLOW_CTX_DAG_ID='dbt_run_models' AIRFLOW_CTX_TASK_ID='run_dbt_models' AIRFLOW_CTX_EXECUTION_DATE='2025-09-04T15:00:00+00:00' AIRFLOW_CTX_TRY_NUMBER='2' AIRFLOW_CTX_DAG_RUN_ID='scheduled__2025-09-04T15:00:00+00:00'
[2025-09-04T16:05:21.972+0000] {taskinstance.py:430} INFO - ::endgroup::
[2025-09-04T16:05:22.010+0000] {subprocess.py:63} INFO - Tmp dir root location: /tmp
[2025-09-04T16:05:22.012+0000] {subprocess.py:75} INFO - Running command: ['/usr/bin/bash', '-c', '\n        cd /usr/app &&         dbt run --profiles-dir /usr/app\n        ']
[2025-09-04T16:05:22.030+0000] {subprocess.py:86} INFO - Output:
[2025-09-04T16:05:26.118+0000] {subprocess.py:93} INFO - [0m16:05:26  Running with dbt=1.7.9
[2025-09-04T16:05:26.508+0000] {subprocess.py:93} INFO - [0m16:05:26  Registered adapter: postgres=1.7.9
[2025-09-04T16:05:26.555+0000] {subprocess.py:93} INFO - [0m16:05:26  [[33mWARNING[0m]: Configuration paths exist in your dbt_project.yml file which do not apply to any resources.
[2025-09-04T16:05:26.556+0000] {subprocess.py:93} INFO - There are 1 unused configuration paths:
[2025-09-04T16:05:26.556+0000] {subprocess.py:93} INFO - - models.my_project.sources
[2025-09-04T16:05:26.583+0000] {subprocess.py:93} INFO - [0m16:05:26  Found 7 models, 7 sources, 0 exposures, 0 metrics, 401 macros, 0 groups, 0 semantic models
[2025-09-04T16:05:26.587+0000] {subprocess.py:93} INFO - [0m16:05:26
[2025-09-04T16:05:26.840+0000] {subprocess.py:93} INFO - [0m16:05:26  Concurrency: 4 threads (target='dev')
[2025-09-04T16:05:26.840+0000] {subprocess.py:93} INFO - [0m16:05:26
[2025-09-04T16:05:26.877+0000] {subprocess.py:93} INFO - [0m16:05:26  1 of 7 START sql view model analytics.stg_AOV .................................. [RUN]
[2025-09-04T16:05:26.878+0000] {subprocess.py:93} INFO - [0m16:05:26  3 of 7 START sql view model analytics.stg_order_details ........................ [RUN]
[2025-09-04T16:05:26.927+0000] {subprocess.py:93} INFO - [0m16:05:26  2 of 7 START sql view model analytics.stg_order_count_year ..................... [RUN]
[2025-09-04T16:05:26.935+0000] {subprocess.py:93} INFO - [0m16:05:26  4 of 7 START sql view model analytics.stg_orders ............................... [RUN]
[2025-09-04T16:05:27.471+0000] {subprocess.py:93} INFO - [0m16:05:27  3 of 7 OK created sql view model analytics.stg_order_details ................... [[32mCREATE VIEW[0m in 0.59s]
[2025-09-04T16:05:27.474+0000] {subprocess.py:93} INFO - [0m16:05:27  1 of 7 OK created sql view model analytics.stg_AOV ............................. [[32mCREATE VIEW[0m in 0.59s]
[2025-09-04T16:05:27.492+0000] {subprocess.py:93} INFO - [0m16:05:27  5 of 7 START sql table model analytics.AOV_chek ................................ [RUN]
[2025-09-04T16:05:27.499+0000] {subprocess.py:93} INFO - [0m16:05:27  2 of 7 OK created sql view model analytics.stg_order_count_year ................ [[32mCREATE VIEW[0m in 0.56s]
[2025-09-04T16:05:27.502+0000] {subprocess.py:93} INFO - [0m16:05:27  4 of 7 OK created sql view model analytics.stg_orders .......................... [[32mCREATE VIEW[0m in 0.55s]
[2025-09-04T16:05:27.505+0000] {subprocess.py:93} INFO - [0m16:05:27  6 of 7 START sql table model analytics.order_count_year ........................ [RUN]
[2025-09-04T16:05:27.512+0000] {subprocess.py:93} INFO - [0m16:05:27  7 of 7 START sql table model analytics.orders_summary .......................... [RUN]
[2025-09-04T16:05:27.726+0000] {subprocess.py:93} INFO - [0m16:05:27  5 of 7 ERROR creating sql table model analytics.AOV_chek ....................... [[31mERROR[0m in 0.22s]
[2025-09-04T16:05:27.989+0000] {subprocess.py:93} INFO - [0m16:05:27  6 of 7 OK created sql table model analytics.order_count_year ................... [[32mSELECT 3[0m in 0.47s]
[2025-09-04T16:05:28.017+0000] {subprocess.py:93} INFO - [0m16:05:28  7 of 7 OK created sql table model analytics.orders_summary ..................... [[32mSELECT 10000[0m in 0.50s]
[2025-09-04T16:05:28.058+0000] {subprocess.py:93} INFO - [0m16:05:28
[2025-09-04T16:05:28.060+0000] {subprocess.py:93} INFO - [0m16:05:28  Finished running 4 view models, 3 table models in 0 hours 0 minutes and 1.47 seconds (1.47s).
[2025-09-04T16:05:28.077+0000] {subprocess.py:93} INFO - [0m16:05:28
[2025-09-04T16:05:28.079+0000] {subprocess.py:93} INFO - [0m16:05:28  [31mCompleted with 1 error and 0 warnings:[0m
[2025-09-04T16:05:28.080+0000] {subprocess.py:93} INFO - [0m16:05:28
[2025-09-04T16:05:28.082+0000] {subprocess.py:93} INFO - [0m16:05:28    Database Error in model AOV_chek (models/marts/AOV_chek.sql)
[2025-09-04T16:05:28.082+0000] {subprocess.py:93} INFO -   syntax error at or near ";"
[2025-09-04T16:05:28.083+0000] {subprocess.py:93} INFO -   LINE 19: group by aov.product_name, aov.category;
[2025-09-04T16:05:28.083+0000] {subprocess.py:93} INFO -                                                   ^
[2025-09-04T16:05:28.083+0000] {subprocess.py:93} INFO -   compiled Code at target/run/my_project/models/marts/AOV_chek.sql
[2025-09-04T16:05:28.085+0000] {subprocess.py:93} INFO - [0m16:05:28
[2025-09-04T16:05:28.095+0000] {subprocess.py:93} INFO - [0m16:05:28  Done. PASS=6 WARN=0 ERROR=1 SKIP=0 TOTAL=7
[2025-09-04T16:05:38.493+0000] {subprocess.py:97} INFO - Command exited with return code 1
[2025-09-04T16:05:38.495+0000] {taskinstance.py:441} INFO - ::group::Post task execution logs
[2025-09-04T16:05:38.517+0000] {taskinstance.py:2905} ERROR - Task failed with exception
Traceback (most recent call last):
  File "/home/airflow/.local/lib/python3.12/site-packages/airflow/models/taskinstance.py", line 465, in _execute_task
    result = _execute_callable(context=context, **execute_callable_kwargs)
             ^^^^^^^^^^^^^^^^^^^^^^^^^^^^^^^^^^^^^^^^^^^^^^^^^^^^^^^^^^^^^
  File "/home/airflow/.local/lib/python3.12/site-packages/airflow/models/taskinstance.py", line 432, in _execute_callable
    return execute_callable(context=context, **execute_callable_kwargs)
           ^^^^^^^^^^^^^^^^^^^^^^^^^^^^^^^^^^^^^^^^^^^^^^^^^^^^^^^^^^^^
  File "/home/airflow/.local/lib/python3.12/site-packages/airflow/models/baseoperator.py", line 401, in wrapper
    return func(self, *args, **kwargs)
           ^^^^^^^^^^^^^^^^^^^^^^^^^^^
  File "/home/airflow/.local/lib/python3.12/site-packages/airflow/operators/bash.py", line 243, in execute
    raise AirflowException(
airflow.exceptions.AirflowException: Bash command failed. The command returned a non-zero exit code 1.
[2025-09-04T16:05:38.529+0000] {taskinstance.py:1206} INFO - Marking task as FAILED. dag_id=dbt_run_models, task_id=run_dbt_models, run_id=scheduled__2025-09-04T15:00:00+00:00, execution_date=20250904T150000, start_date=20250904T160521, end_date=20250904T160538
[2025-09-04T16:05:38.566+0000] {standard_task_runner.py:110} ERROR - Failed to execute job 1014 for task run_dbt_models (Bash command failed. The command returned a non-zero exit code 1.; 547)
[2025-09-04T16:05:38.599+0000] {local_task_job_runner.py:243} INFO - Task exited with return code 1
[2025-09-04T16:05:38.668+0000] {taskinstance.py:3503} INFO - 0 downstream tasks scheduled from follow-on schedule check
[2025-09-04T16:05:38.682+0000] {local_task_job_runner.py:222} INFO - ::endgroup::
