[2025-09-03T04:58:09.772+0000] {local_task_job_runner.py:120} INFO - ::group::Pre task execution logs
[2025-09-03T04:58:09.918+0000] {taskinstance.py:2076} INFO - Dependencies all met for dep_context=non-requeueable deps ti=<TaskInstance: dbt_run_models.run_dbt_models scheduled__2025-09-03T03:00:00+00:00 [queued]>
[2025-09-03T04:58:09.950+0000] {taskinstance.py:2076} INFO - Dependencies all met for dep_context=requeueable deps ti=<TaskInstance: dbt_run_models.run_dbt_models scheduled__2025-09-03T03:00:00+00:00 [queued]>
[2025-09-03T04:58:09.951+0000] {taskinstance.py:2306} INFO - Starting attempt 1 of 2
[2025-09-03T04:58:10.019+0000] {taskinstance.py:2330} INFO - Executing <Task(BashOperator): run_dbt_models> on 2025-09-03 03:00:00+00:00
[2025-09-03T04:58:10.042+0000] {warnings.py:112} WARNING - /home/airflow/.local/lib/python3.12/site-packages/airflow/task/task_runner/standard_task_runner.py:62: DeprecationWarning: This process (pid=2944) is multi-threaded, use of fork() may lead to deadlocks in the child.
  pid = os.fork()

[2025-09-03T04:58:10.048+0000] {standard_task_runner.py:64} INFO - Started process 2945 to run task
[2025-09-03T04:58:10.058+0000] {standard_task_runner.py:90} INFO - Running: ['airflow', 'tasks', 'run', 'dbt_run_models', 'run_dbt_models', 'scheduled__2025-09-03T03:00:00+00:00', '--job-id', '920', '--raw', '--subdir', 'DAGS_FOLDER/dbt_dag.py', '--cfg-path', '/tmp/tmpamvd6agi']
[2025-09-03T04:58:10.070+0000] {standard_task_runner.py:91} INFO - Job 920: Subtask run_dbt_models
[2025-09-03T04:58:10.120+0000] {warnings.py:112} WARNING - /home/airflow/.local/lib/python3.12/site-packages/airflow/settings.py:195: DeprecationWarning: The sql_alchemy_conn option in [core] has been moved to the sql_alchemy_conn option in [database] - the old setting has been used, but please update your config.
  SQL_ALCHEMY_CONN = conf.get("database", "SQL_ALCHEMY_CONN")

[2025-09-03T04:58:10.327+0000] {task_command.py:426} INFO - Running <TaskInstance: dbt_run_models.run_dbt_models scheduled__2025-09-03T03:00:00+00:00 [running]> on host b5ea13053d47
[2025-09-03T04:58:10.795+0000] {taskinstance.py:2648} INFO - Exporting env vars: AIRFLOW_CTX_DAG_OWNER='airflow' AIRFLOW_CTX_DAG_ID='dbt_run_models' AIRFLOW_CTX_TASK_ID='run_dbt_models' AIRFLOW_CTX_EXECUTION_DATE='2025-09-03T03:00:00+00:00' AIRFLOW_CTX_TRY_NUMBER='1' AIRFLOW_CTX_DAG_RUN_ID='scheduled__2025-09-03T03:00:00+00:00'
[2025-09-03T04:58:10.797+0000] {taskinstance.py:430} INFO - ::endgroup::
[2025-09-03T04:58:10.859+0000] {subprocess.py:63} INFO - Tmp dir root location: /tmp
[2025-09-03T04:58:10.860+0000] {subprocess.py:75} INFO - Running command: ['/usr/bin/bash', '-c', '\n        cd /usr/app &&         dbt run --profiles-dir /usr/app\n        ']
[2025-09-03T04:58:10.886+0000] {subprocess.py:86} INFO - Output:
[2025-09-03T04:58:16.178+0000] {subprocess.py:93} INFO - [0m04:58:16  Running with dbt=1.7.9
[2025-09-03T04:58:16.937+0000] {subprocess.py:93} INFO - [0m04:58:16  Registered adapter: postgres=1.7.9
[2025-09-03T04:58:17.235+0000] {subprocess.py:93} INFO - [0m04:58:17  Encountered an error:
[2025-09-03T04:58:17.236+0000] {subprocess.py:93} INFO - Compilation Error
[2025-09-03T04:58:17.237+0000] {subprocess.py:93} INFO -   Model 'model.my_project.order_count_year' (models/marts/order_count_year.sql) depends on a node named 'orders' in package or project 'northwind' which was not found
[2025-09-03T04:58:18.418+0000] {subprocess.py:97} INFO - Command exited with return code 2
[2025-09-03T04:58:18.419+0000] {taskinstance.py:441} INFO - ::group::Post task execution logs
[2025-09-03T04:58:18.432+0000] {taskinstance.py:2905} ERROR - Task failed with exception
Traceback (most recent call last):
  File "/home/airflow/.local/lib/python3.12/site-packages/airflow/models/taskinstance.py", line 465, in _execute_task
    result = _execute_callable(context=context, **execute_callable_kwargs)
             ^^^^^^^^^^^^^^^^^^^^^^^^^^^^^^^^^^^^^^^^^^^^^^^^^^^^^^^^^^^^^
  File "/home/airflow/.local/lib/python3.12/site-packages/airflow/models/taskinstance.py", line 432, in _execute_callable
    return execute_callable(context=context, **execute_callable_kwargs)
           ^^^^^^^^^^^^^^^^^^^^^^^^^^^^^^^^^^^^^^^^^^^^^^^^^^^^^^^^^^^^
  File "/home/airflow/.local/lib/python3.12/site-packages/airflow/models/baseoperator.py", line 401, in wrapper
    return func(self, *args, **kwargs)
           ^^^^^^^^^^^^^^^^^^^^^^^^^^^
  File "/home/airflow/.local/lib/python3.12/site-packages/airflow/operators/bash.py", line 243, in execute
    raise AirflowException(
airflow.exceptions.AirflowException: Bash command failed. The command returned a non-zero exit code 2.
[2025-09-03T04:58:18.444+0000] {taskinstance.py:1206} INFO - Marking task as UP_FOR_RETRY. dag_id=dbt_run_models, task_id=run_dbt_models, run_id=scheduled__2025-09-03T03:00:00+00:00, execution_date=20250903T030000, start_date=20250903T045809, end_date=20250903T045818
[2025-09-03T04:58:18.465+0000] {standard_task_runner.py:110} ERROR - Failed to execute job 920 for task run_dbt_models (Bash command failed. The command returned a non-zero exit code 2.; 2945)
[2025-09-03T04:58:18.508+0000] {local_task_job_runner.py:243} INFO - Task exited with return code 1
[2025-09-03T04:58:18.548+0000] {taskinstance.py:3503} INFO - 0 downstream tasks scheduled from follow-on schedule check
[2025-09-03T04:58:18.552+0000] {local_task_job_runner.py:222} INFO - ::endgroup::
