[2025-08-27T04:29:55.844+0000] {local_task_job_runner.py:120} INFO - ::group::Pre task execution logs
[2025-08-27T04:29:55.906+0000] {taskinstance.py:2076} INFO - Dependencies all met for dep_context=non-requeueable deps ti=<TaskInstance: daily_generate_orders.generate_new_data scheduled__2025-08-26T18:00:00+00:00 [queued]>
[2025-08-27T04:29:55.928+0000] {taskinstance.py:2076} INFO - Dependencies all met for dep_context=requeueable deps ti=<TaskInstance: daily_generate_orders.generate_new_data scheduled__2025-08-26T18:00:00+00:00 [queued]>
[2025-08-27T04:29:55.930+0000] {taskinstance.py:2306} INFO - Starting attempt 1 of 1
[2025-08-27T04:29:55.968+0000] {taskinstance.py:2330} INFO - Executing <Task(PythonOperator): generate_new_data> on 2025-08-26 18:00:00+00:00
[2025-08-27T04:29:55.994+0000] {standard_task_runner.py:90} INFO - Running: ['airflow', 'tasks', 'run', 'daily_generate_orders', 'generate_new_data', 'scheduled__2025-08-26T18:00:00+00:00', '--job-id', '662', '--raw', '--subdir', 'DAGS_FOLDER/generate_fake_shop_csv.py', '--cfg-path', '/tmp/tmpwohu56k_']
[2025-08-27T04:29:55.999+0000] {standard_task_runner.py:91} INFO - Job 662: Subtask generate_new_data
[2025-08-27T04:29:55.997+0000] {warnings.py:112} WARNING - /home/airflow/.local/lib/python3.12/site-packages/airflow/task/task_runner/standard_task_runner.py:62: DeprecationWarning: This process (pid=1351) is multi-threaded, use of fork() may lead to deadlocks in the child.
  pid = os.fork()

[2025-08-27T04:29:56.002+0000] {standard_task_runner.py:64} INFO - Started process 1353 to run task
[2025-08-27T04:29:56.031+0000] {warnings.py:112} WARNING - /home/airflow/.local/lib/python3.12/site-packages/airflow/settings.py:195: DeprecationWarning: The sql_alchemy_conn option in [core] has been moved to the sql_alchemy_conn option in [database] - the old setting has been used, but please update your config.
  SQL_ALCHEMY_CONN = conf.get("database", "SQL_ALCHEMY_CONN")

[2025-08-27T04:29:56.080+0000] {task_command.py:426} INFO - Running <TaskInstance: daily_generate_orders.generate_new_data scheduled__2025-08-26T18:00:00+00:00 [running]> on host b5ea13053d47
[2025-08-27T04:29:56.242+0000] {taskinstance.py:2648} INFO - Exporting env vars: AIRFLOW_CTX_DAG_OWNER='airflow' AIRFLOW_CTX_DAG_ID='daily_generate_orders' AIRFLOW_CTX_TASK_ID='generate_new_data' AIRFLOW_CTX_EXECUTION_DATE='2025-08-26T18:00:00+00:00' AIRFLOW_CTX_TRY_NUMBER='1' AIRFLOW_CTX_DAG_RUN_ID='scheduled__2025-08-26T18:00:00+00:00'
[2025-08-27T04:29:56.244+0000] {taskinstance.py:430} INFO - ::endgroup::
[2025-08-27T04:29:56.442+0000] {taskinstance.py:441} INFO - ::group::Post task execution logs
[2025-08-27T04:29:56.443+0000] {taskinstance.py:2905} ERROR - Task failed with exception
Traceback (most recent call last):
  File "/home/airflow/.local/lib/python3.12/site-packages/airflow/models/taskinstance.py", line 465, in _execute_task
    result = _execute_callable(context=context, **execute_callable_kwargs)
             ^^^^^^^^^^^^^^^^^^^^^^^^^^^^^^^^^^^^^^^^^^^^^^^^^^^^^^^^^^^^^
  File "/home/airflow/.local/lib/python3.12/site-packages/airflow/models/taskinstance.py", line 432, in _execute_callable
    return execute_callable(context=context, **execute_callable_kwargs)
           ^^^^^^^^^^^^^^^^^^^^^^^^^^^^^^^^^^^^^^^^^^^^^^^^^^^^^^^^^^^^
  File "/home/airflow/.local/lib/python3.12/site-packages/airflow/models/baseoperator.py", line 401, in wrapper
    return func(self, *args, **kwargs)
           ^^^^^^^^^^^^^^^^^^^^^^^^^^^
  File "/home/airflow/.local/lib/python3.12/site-packages/airflow/operators/python.py", line 235, in execute
    return_value = self.execute_callable()
                   ^^^^^^^^^^^^^^^^^^^^^^^
  File "/home/airflow/.local/lib/python3.12/site-packages/airflow/operators/python.py", line 252, in execute_callable
    return self.python_callable(*self.op_args, **self.op_kwargs)
           ^^^^^^^^^^^^^^^^^^^^^^^^^^^^^^^^^^^^^^^^^^^^^^^^^^^^^
  File "/opt/airflow/dags/generate_fake_shop_csv.py", line 145, in generate_new_data
    orders.to_csv(os.path.join(CSV_FOLDER, "orders.csv"), index=False)
  File "/home/airflow/.local/lib/python3.12/site-packages/pandas/core/generic.py", line 3902, in to_csv
    return DataFrameRenderer(formatter).to_csv(
           ^^^^^^^^^^^^^^^^^^^^^^^^^^^^^^^^^^^^
  File "/home/airflow/.local/lib/python3.12/site-packages/pandas/io/formats/format.py", line 1152, in to_csv
    csv_formatter.save()
  File "/home/airflow/.local/lib/python3.12/site-packages/pandas/io/formats/csvs.py", line 247, in save
    with get_handle(
         ^^^^^^^^^^^
  File "/home/airflow/.local/lib/python3.12/site-packages/pandas/io/common.py", line 863, in get_handle
    handle = open(
             ^^^^^
PermissionError: [Errno 13] Permission denied: '/opt/airflow/plugins/orders.csv'
[2025-08-27T04:29:56.480+0000] {taskinstance.py:1206} INFO - Marking task as FAILED. dag_id=daily_generate_orders, task_id=generate_new_data, run_id=scheduled__2025-08-26T18:00:00+00:00, execution_date=20250826T180000, start_date=20250827T042955, end_date=20250827T042956
[2025-08-27T04:29:56.514+0000] {standard_task_runner.py:110} ERROR - Failed to execute job 662 for task generate_new_data ([Errno 13] Permission denied: '/opt/airflow/plugins/orders.csv'; 1353)
[2025-08-27T04:29:56.558+0000] {local_task_job_runner.py:243} INFO - Task exited with return code 1
[2025-08-27T04:29:56.596+0000] {taskinstance.py:3503} INFO - 0 downstream tasks scheduled from follow-on schedule check
[2025-08-27T04:29:56.604+0000] {local_task_job_runner.py:222} INFO - ::endgroup::
