[2025-08-22T00:05:04.818+0000] {local_task_job_runner.py:120} INFO - ::group::Pre task execution logs
[2025-08-22T00:05:04.889+0000] {taskinstance.py:2076} INFO - Dependencies all met for dep_context=non-requeueable deps ti=<TaskInstance: dbt_run_models.run_dbt_models scheduled__2025-08-21T21:00:00+00:00 [queued]>
[2025-08-22T00:05:04.911+0000] {taskinstance.py:2076} INFO - Dependencies all met for dep_context=requeueable deps ti=<TaskInstance: dbt_run_models.run_dbt_models scheduled__2025-08-21T21:00:00+00:00 [queued]>
[2025-08-22T00:05:04.912+0000] {taskinstance.py:2306} INFO - Starting attempt 2 of 2
[2025-08-22T00:05:04.942+0000] {taskinstance.py:2330} INFO - Executing <Task(BashOperator): run_dbt_models> on 2025-08-21 21:00:00+00:00
[2025-08-22T00:05:04.949+0000] {warnings.py:112} WARNING - /home/airflow/.local/lib/python3.12/site-packages/airflow/task/task_runner/standard_task_runner.py:62: DeprecationWarning: This process (pid=265) is multi-threaded, use of fork() may lead to deadlocks in the child.
  pid = os.fork()

[2025-08-22T00:05:04.950+0000] {standard_task_runner.py:64} INFO - Started process 266 to run task
[2025-08-22T00:05:04.954+0000] {standard_task_runner.py:90} INFO - Running: ['airflow', 'tasks', 'run', 'dbt_run_models', 'run_dbt_models', 'scheduled__2025-08-21T21:00:00+00:00', '--job-id', '122', '--raw', '--subdir', 'DAGS_FOLDER/dbt_dag.py', '--cfg-path', '/tmp/tmpf0gm_958']
[2025-08-22T00:05:04.956+0000] {standard_task_runner.py:91} INFO - Job 122: Subtask run_dbt_models
[2025-08-22T00:05:04.994+0000] {warnings.py:112} WARNING - /home/airflow/.local/lib/python3.12/site-packages/airflow/settings.py:195: DeprecationWarning: The sql_alchemy_conn option in [core] has been moved to the sql_alchemy_conn option in [database] - the old setting has been used, but please update your config.
  SQL_ALCHEMY_CONN = conf.get("database", "SQL_ALCHEMY_CONN")

[2025-08-22T00:05:05.086+0000] {task_command.py:426} INFO - Running <TaskInstance: dbt_run_models.run_dbt_models scheduled__2025-08-21T21:00:00+00:00 [running]> on host 71579c071e19
[2025-08-22T00:05:05.283+0000] {taskinstance.py:2648} INFO - Exporting env vars: AIRFLOW_CTX_DAG_OWNER='airflow' AIRFLOW_CTX_DAG_ID='dbt_run_models' AIRFLOW_CTX_TASK_ID='run_dbt_models' AIRFLOW_CTX_EXECUTION_DATE='2025-08-21T21:00:00+00:00' AIRFLOW_CTX_TRY_NUMBER='2' AIRFLOW_CTX_DAG_RUN_ID='scheduled__2025-08-21T21:00:00+00:00'
[2025-08-22T00:05:05.284+0000] {taskinstance.py:430} INFO - ::endgroup::
[2025-08-22T00:05:05.329+0000] {subprocess.py:63} INFO - Tmp dir root location: /tmp
[2025-08-22T00:05:05.330+0000] {subprocess.py:75} INFO - Running command: ['/usr/bin/bash', '-c', '\n        cd /usr/app &&         dbt run --profiles-dir /usr/app\n        ']
[2025-08-22T00:05:05.346+0000] {subprocess.py:86} INFO - Output:
[2025-08-22T00:05:05.348+0000] {subprocess.py:93} INFO - /usr/bin/bash: line 2: dbt: command not found
[2025-08-22T00:05:05.349+0000] {subprocess.py:97} INFO - Command exited with return code 127
[2025-08-22T00:05:05.351+0000] {taskinstance.py:441} INFO - ::group::Post task execution logs
[2025-08-22T00:05:05.370+0000] {taskinstance.py:2905} ERROR - Task failed with exception
Traceback (most recent call last):
  File "/home/airflow/.local/lib/python3.12/site-packages/airflow/models/taskinstance.py", line 465, in _execute_task
    result = _execute_callable(context=context, **execute_callable_kwargs)
             ^^^^^^^^^^^^^^^^^^^^^^^^^^^^^^^^^^^^^^^^^^^^^^^^^^^^^^^^^^^^^
  File "/home/airflow/.local/lib/python3.12/site-packages/airflow/models/taskinstance.py", line 432, in _execute_callable
    return execute_callable(context=context, **execute_callable_kwargs)
           ^^^^^^^^^^^^^^^^^^^^^^^^^^^^^^^^^^^^^^^^^^^^^^^^^^^^^^^^^^^^
  File "/home/airflow/.local/lib/python3.12/site-packages/airflow/models/baseoperator.py", line 401, in wrapper
    return func(self, *args, **kwargs)
           ^^^^^^^^^^^^^^^^^^^^^^^^^^^
  File "/home/airflow/.local/lib/python3.12/site-packages/airflow/operators/bash.py", line 243, in execute
    raise AirflowException(
airflow.exceptions.AirflowException: Bash command failed. The command returned a non-zero exit code 127.
[2025-08-22T00:05:05.385+0000] {taskinstance.py:1206} INFO - Marking task as FAILED. dag_id=dbt_run_models, task_id=run_dbt_models, run_id=scheduled__2025-08-21T21:00:00+00:00, execution_date=20250821T210000, start_date=20250822T000504, end_date=20250822T000505
[2025-08-22T00:05:05.416+0000] {standard_task_runner.py:110} ERROR - Failed to execute job 122 for task run_dbt_models (Bash command failed. The command returned a non-zero exit code 127.; 266)
[2025-08-22T00:05:05.447+0000] {local_task_job_runner.py:243} INFO - Task exited with return code 1
[2025-08-22T00:05:05.494+0000] {taskinstance.py:3503} INFO - 0 downstream tasks scheduled from follow-on schedule check
[2025-08-22T00:05:05.504+0000] {local_task_job_runner.py:222} INFO - ::endgroup::
