[2025-08-26T15:30:03.458+0000] {local_task_job_runner.py:120} INFO - ::group::Pre task execution logs
[2025-08-26T15:30:03.513+0000] {taskinstance.py:2076} INFO - Dependencies all met for dep_context=non-requeueable deps ti=<TaskInstance: import_csv_to_postgres.load_csv_to_postgres scheduled__2025-08-26T15:00:00+00:00 [queued]>
[2025-08-26T15:30:03.520+0000] {taskinstance.py:2076} INFO - Dependencies all met for dep_context=requeueable deps ti=<TaskInstance: import_csv_to_postgres.load_csv_to_postgres scheduled__2025-08-26T15:00:00+00:00 [queued]>
[2025-08-26T15:30:03.521+0000] {taskinstance.py:2306} INFO - Starting attempt 1 of 1
[2025-08-26T15:30:03.536+0000] {taskinstance.py:2330} INFO - Executing <Task(PythonOperator): load_csv_to_postgres> on 2025-08-26 15:00:00+00:00
[2025-08-26T15:30:03.545+0000] {warnings.py:112} WARNING - /home/airflow/.local/lib/python3.12/site-packages/airflow/task/task_runner/standard_task_runner.py:62: DeprecationWarning: This process (pid=1182) is multi-threaded, use of fork() may lead to deadlocks in the child.
  pid = os.fork()

[2025-08-26T15:30:03.546+0000] {standard_task_runner.py:64} INFO - Started process 1184 to run task
[2025-08-26T15:30:03.547+0000] {standard_task_runner.py:90} INFO - Running: ['airflow', 'tasks', 'run', 'import_csv_to_postgres', 'load_csv_to_postgres', 'scheduled__2025-08-26T15:00:00+00:00', '--job-id', '623', '--raw', '--subdir', 'DAGS_FOLDER/csv_to_postgres_dag.py', '--cfg-path', '/tmp/tmpqk9z_kzy']
[2025-08-26T15:30:03.551+0000] {standard_task_runner.py:91} INFO - Job 623: Subtask load_csv_to_postgres
[2025-08-26T15:30:03.580+0000] {warnings.py:112} WARNING - /home/airflow/.local/lib/python3.12/site-packages/airflow/settings.py:195: DeprecationWarning: The sql_alchemy_conn option in [core] has been moved to the sql_alchemy_conn option in [database] - the old setting has been used, but please update your config.
  SQL_ALCHEMY_CONN = conf.get("database", "SQL_ALCHEMY_CONN")

[2025-08-26T15:30:03.645+0000] {task_command.py:426} INFO - Running <TaskInstance: import_csv_to_postgres.load_csv_to_postgres scheduled__2025-08-26T15:00:00+00:00 [running]> on host b5ea13053d47
[2025-08-26T15:30:03.824+0000] {taskinstance.py:2648} INFO - Exporting env vars: AIRFLOW_CTX_DAG_OWNER='airflow' AIRFLOW_CTX_DAG_ID='import_csv_to_postgres' AIRFLOW_CTX_TASK_ID='load_csv_to_postgres' AIRFLOW_CTX_EXECUTION_DATE='2025-08-26T15:00:00+00:00' AIRFLOW_CTX_TRY_NUMBER='1' AIRFLOW_CTX_DAG_RUN_ID='scheduled__2025-08-26T15:00:00+00:00'
[2025-08-26T15:30:03.826+0000] {taskinstance.py:430} INFO - ::endgroup::
[2025-08-26T15:30:03.884+0000] {base.py:84} INFO - Using connection ID 'postgres_conn' for task execution.
[2025-08-26T15:30:03.898+0000] {logging_mixin.py:188} INFO - ðŸ—‘ Ð¢Ð°Ð±Ð»Ð¸Ñ†Ð° order_items Ð¾Ñ‡Ð¸Ñ‰ÐµÐ½Ð°
[2025-08-26T15:30:03.936+0000] {logging_mixin.py:188} INFO - ðŸ—‘ Ð¢Ð°Ð±Ð»Ð¸Ñ†Ð° orders Ð¾Ñ‡Ð¸Ñ‰ÐµÐ½Ð°
[2025-08-26T15:30:03.951+0000] {logging_mixin.py:188} INFO - ðŸ—‘ Ð¢Ð°Ð±Ð»Ð¸Ñ†Ð° shipments Ð¾Ñ‡Ð¸Ñ‰ÐµÐ½Ð°
[2025-08-26T15:30:03.967+0000] {logging_mixin.py:188} INFO - ðŸ—‘ Ð¢Ð°Ð±Ð»Ð¸Ñ†Ð° customers Ð¾Ñ‡Ð¸Ñ‰ÐµÐ½Ð°
[2025-08-26T15:30:03.980+0000] {logging_mixin.py:188} INFO - ðŸ—‘ Ð¢Ð°Ð±Ð»Ð¸Ñ†Ð° products Ð¾Ñ‡Ð¸Ñ‰ÐµÐ½Ð°
[2025-08-26T15:30:04.487+0000] {logging_mixin.py:188} INFO - âœ… Ð—Ð°Ð³Ñ€ÑƒÐ¶ÐµÐ½ Ñ„Ð°Ð¹Ð» customers.csv Ð² Ñ‚Ð°Ð±Ð»Ð¸Ñ†Ñƒ customers
[2025-08-26T15:30:04.556+0000] {logging_mixin.py:188} INFO - âœ… Ð—Ð°Ð³Ñ€ÑƒÐ¶ÐµÐ½ Ñ„Ð°Ð¹Ð» products.csv Ð² Ñ‚Ð°Ð±Ð»Ð¸Ñ†Ñƒ products
[2025-08-26T15:30:05.040+0000] {logging_mixin.py:188} INFO - âœ… Ð—Ð°Ð³Ñ€ÑƒÐ¶ÐµÐ½ Ñ„Ð°Ð¹Ð» shipments.csv Ð² Ñ‚Ð°Ð±Ð»Ð¸Ñ†Ñƒ shipments
[2025-08-26T15:30:05.691+0000] {logging_mixin.py:188} INFO - âœ… Ð—Ð°Ð³Ñ€ÑƒÐ¶ÐµÐ½ Ñ„Ð°Ð¹Ð» orders.csv Ð² Ñ‚Ð°Ð±Ð»Ð¸Ñ†Ñƒ orders
[2025-08-26T15:30:06.847+0000] {taskinstance.py:441} INFO - ::group::Post task execution logs
[2025-08-26T15:30:06.848+0000] {taskinstance.py:2905} ERROR - Task failed with exception
Traceback (most recent call last):
  File "/home/airflow/.local/lib/python3.12/site-packages/sqlalchemy/engine/base.py", line 1890, in _execute_context
    self.dialect.do_executemany(
  File "/home/airflow/.local/lib/python3.12/site-packages/sqlalchemy/dialects/postgresql/psycopg2.py", line 982, in do_executemany
    context._psycopg2_fetched_rows = xtras.execute_values(
                                     ^^^^^^^^^^^^^^^^^^^^^
  File "/home/airflow/.local/lib/python3.12/site-packages/psycopg2/extras.py", line 1299, in execute_values
    cur.execute(b''.join(parts))
psycopg2.errors.UniqueViolation: duplicate key value violates unique constraint "order_items_pkey"
DETAIL:  Key (order_item_id)=(20001) already exists.


The above exception was the direct cause of the following exception:

Traceback (most recent call last):
  File "/home/airflow/.local/lib/python3.12/site-packages/airflow/models/taskinstance.py", line 465, in _execute_task
    result = _execute_callable(context=context, **execute_callable_kwargs)
             ^^^^^^^^^^^^^^^^^^^^^^^^^^^^^^^^^^^^^^^^^^^^^^^^^^^^^^^^^^^^^
  File "/home/airflow/.local/lib/python3.12/site-packages/airflow/models/taskinstance.py", line 432, in _execute_callable
    return execute_callable(context=context, **execute_callable_kwargs)
           ^^^^^^^^^^^^^^^^^^^^^^^^^^^^^^^^^^^^^^^^^^^^^^^^^^^^^^^^^^^^
  File "/home/airflow/.local/lib/python3.12/site-packages/airflow/models/baseoperator.py", line 401, in wrapper
    return func(self, *args, **kwargs)
           ^^^^^^^^^^^^^^^^^^^^^^^^^^^
  File "/home/airflow/.local/lib/python3.12/site-packages/airflow/operators/python.py", line 235, in execute
    return_value = self.execute_callable()
                   ^^^^^^^^^^^^^^^^^^^^^^^
  File "/home/airflow/.local/lib/python3.12/site-packages/airflow/operators/python.py", line 252, in execute_callable
    return self.python_callable(*self.op_args, **self.op_kwargs)
           ^^^^^^^^^^^^^^^^^^^^^^^^^^^^^^^^^^^^^^^^^^^^^^^^^^^^^
  File "/opt/airflow/dags/csv_to_postgres_dag.py", line 74, in load_csv_to_postgres
    df.to_sql(table_name, engine, if_exists="append", index=False, dtype=dtype_mapping)
  File "/home/airflow/.local/lib/python3.12/site-packages/pandas/util/_decorators.py", line 333, in wrapper
    return func(*args, **kwargs)
           ^^^^^^^^^^^^^^^^^^^^^
  File "/home/airflow/.local/lib/python3.12/site-packages/pandas/core/generic.py", line 3008, in to_sql
    return sql.to_sql(
           ^^^^^^^^^^^
  File "/home/airflow/.local/lib/python3.12/site-packages/pandas/io/sql.py", line 788, in to_sql
    return pandas_sql.to_sql(
           ^^^^^^^^^^^^^^^^^^
  File "/home/airflow/.local/lib/python3.12/site-packages/pandas/io/sql.py", line 1958, in to_sql
    total_inserted = sql_engine.insert_records(
                     ^^^^^^^^^^^^^^^^^^^^^^^^^^
  File "/home/airflow/.local/lib/python3.12/site-packages/pandas/io/sql.py", line 1507, in insert_records
    raise err
  File "/home/airflow/.local/lib/python3.12/site-packages/pandas/io/sql.py", line 1498, in insert_records
    return table.insert(chunksize=chunksize, method=method)
           ^^^^^^^^^^^^^^^^^^^^^^^^^^^^^^^^^^^^^^^^^^^^^^^^
  File "/home/airflow/.local/lib/python3.12/site-packages/pandas/io/sql.py", line 1059, in insert
    num_inserted = exec_insert(conn, keys, chunk_iter)
                   ^^^^^^^^^^^^^^^^^^^^^^^^^^^^^^^^^^^
  File "/home/airflow/.local/lib/python3.12/site-packages/pandas/io/sql.py", line 951, in _execute_insert
    result = conn.execute(self.table.insert(), data)
             ^^^^^^^^^^^^^^^^^^^^^^^^^^^^^^^^^^^^^^^
  File "/home/airflow/.local/lib/python3.12/site-packages/sqlalchemy/engine/base.py", line 1385, in execute
    return meth(self, multiparams, params, _EMPTY_EXECUTION_OPTS)
           ^^^^^^^^^^^^^^^^^^^^^^^^^^^^^^^^^^^^^^^^^^^^^^^^^^^^^^
  File "/home/airflow/.local/lib/python3.12/site-packages/sqlalchemy/sql/elements.py", line 334, in _execute_on_connection
    return connection._execute_clauseelement(
           ^^^^^^^^^^^^^^^^^^^^^^^^^^^^^^^^^^
  File "/home/airflow/.local/lib/python3.12/site-packages/sqlalchemy/engine/base.py", line 1577, in _execute_clauseelement
    ret = self._execute_context(
          ^^^^^^^^^^^^^^^^^^^^^^
  File "/home/airflow/.local/lib/python3.12/site-packages/sqlalchemy/engine/base.py", line 1953, in _execute_context
    self._handle_dbapi_exception(
  File "/home/airflow/.local/lib/python3.12/site-packages/sqlalchemy/engine/base.py", line 2134, in _handle_dbapi_exception
    util.raise_(
  File "/home/airflow/.local/lib/python3.12/site-packages/sqlalchemy/util/compat.py", line 211, in raise_
    raise exception
  File "/home/airflow/.local/lib/python3.12/site-packages/sqlalchemy/engine/base.py", line 1890, in _execute_context
    self.dialect.do_executemany(
  File "/home/airflow/.local/lib/python3.12/site-packages/sqlalchemy/dialects/postgresql/psycopg2.py", line 982, in do_executemany
    context._psycopg2_fetched_rows = xtras.execute_values(
                                     ^^^^^^^^^^^^^^^^^^^^^
  File "/home/airflow/.local/lib/python3.12/site-packages/psycopg2/extras.py", line 1299, in execute_values
    cur.execute(b''.join(parts))
sqlalchemy.exc.IntegrityError: (psycopg2.errors.UniqueViolation) duplicate key value violates unique constraint "order_items_pkey"
DETAIL:  Key (order_item_id)=(20001) already exists.

[SQL: INSERT INTO order_items (order_item_id, order_id, product_id, quantity, price_at_purchase, unit_price) VALUES (%(order_item_id)s, %(order_id)s, %(product_id)s, %(quantity)s, %(price_at_purchase)s, %(unit_price)s)]
[parameters: ({'order_item_id': 1, 'order_id': 6550, 'product_id': 1032, 'quantity': 1, 'price_at_purchase': 342.92, 'unit_price': None}, {'order_item_id': 2, 'order_id': 7324, 'product_id': 1695, 'quantity': 1, 'price_at_purchase': 955.86, 'unit_price': None}, {'order_item_id': 3, 'order_id': 11952, 'product_id': 1962, 'quantity': 1, 'price_at_purchase': 909.45, 'unit_price': None}, {'order_item_id': 4, 'order_id': 8938, 'product_id': 1958, 'quantity': 1, 'price_at_purchase': 984.91, 'unit_price': None}, {'order_item_id': 5, 'order_id': 4238, 'product_id': 1880, 'quantity': 1, 'price_at_purchase': 649.18, 'unit_price': None}, {'order_item_id': 6, 'order_id': 14235, 'product_id': 672, 'quantity': 1, 'price_at_purchase': 695.76, 'unit_price': None}, {'order_item_id': 7, 'order_id': 10944, 'product_id': 1, 'quantity': 1, 'price_at_purchase': 54.83, 'unit_price': None}, {'order_item_id': 8, 'order_id': 11075, 'product_id': 827, 'quantity': 1, 'price_at_purchase': 320.24, 'unit_price': None}  ... displaying 10 of 20061 total bound parameter sets ...  {'order_item_id': 20026, 'order_id': 15026, 'product_id': 1200, 'quantity': 5, 'price_at_purchase': None, 'unit_price': 33.02}, {'order_item_id': 20026, 'order_id': 15026, 'product_id': 8, 'quantity': 1, 'price_at_purchase': None, 'unit_price': 378.12})]
(Background on this error at: https://sqlalche.me/e/14/gkpj)
[2025-08-26T15:30:06.870+0000] {taskinstance.py:1206} INFO - Marking task as FAILED. dag_id=import_csv_to_postgres, task_id=load_csv_to_postgres, run_id=scheduled__2025-08-26T15:00:00+00:00, execution_date=20250826T150000, start_date=20250826T153003, end_date=20250826T153006
[2025-08-26T15:30:06.886+0000] {standard_task_runner.py:110} ERROR - Failed to execute job 623 for task load_csv_to_postgres ((psycopg2.errors.UniqueViolation) duplicate key value violates unique constraint "order_items_pkey"
DETAIL:  Key (order_item_id)=(20001) already exists.

[SQL: INSERT INTO order_items (order_item_id, order_id, product_id, quantity, price_at_purchase, unit_price) VALUES (%(order_item_id)s, %(order_id)s, %(product_id)s, %(quantity)s, %(price_at_purchase)s, %(unit_price)s)]
[parameters: ({'order_item_id': 1, 'order_id': 6550, 'product_id': 1032, 'quantity': 1, 'price_at_purchase': 342.92, 'unit_price': None}, {'order_item_id': 2, 'order_id': 7324, 'product_id': 1695, 'quantity': 1, 'price_at_purchase': 955.86, 'unit_price': None}, {'order_item_id': 3, 'order_id': 11952, 'product_id': 1962, 'quantity': 1, 'price_at_purchase': 909.45, 'unit_price': None}, {'order_item_id': 4, 'order_id': 8938, 'product_id': 1958, 'quantity': 1, 'price_at_purchase': 984.91, 'unit_price': None}, {'order_item_id': 5, 'order_id': 4238, 'product_id': 1880, 'quantity': 1, 'price_at_purchase': 649.18, 'unit_price': None}, {'order_item_id': 6, 'order_id': 14235, 'product_id': 672, 'quantity': 1, 'price_at_purchase': 695.76, 'unit_price': None}, {'order_item_id': 7, 'order_id': 10944, 'product_id': 1, 'quantity': 1, 'price_at_purchase': 54.83, 'unit_price': None}, {'order_item_id': 8, 'order_id': 11075, 'product_id': 827, 'quantity': 1, 'price_at_purchase': 320.24, 'unit_price': None}  ... displaying 10 of 20061 total bound parameter sets ...  {'order_item_id': 20026, 'order_id': 15026, 'product_id': 1200, 'quantity': 5, 'price_at_purchase': None, 'unit_price': 33.02}, {'order_item_id': 20026, 'order_id': 15026, 'product_id': 8, 'quantity': 1, 'price_at_purchase': None, 'unit_price': 378.12})]
(Background on this error at: https://sqlalche.me/e/14/gkpj); 1184)
[2025-08-26T15:30:06.908+0000] {local_task_job_runner.py:243} INFO - Task exited with return code 1
[2025-08-26T15:30:06.926+0000] {taskinstance.py:3503} INFO - 0 downstream tasks scheduled from follow-on schedule check
[2025-08-26T15:30:06.930+0000] {local_task_job_runner.py:222} INFO - ::endgroup::
[2025-08-26T15:44:11.970+0000] {local_task_job_runner.py:120} INFO - ::group::Pre task execution logs
[2025-08-26T15:44:12.018+0000] {taskinstance.py:2076} INFO - Dependencies all met for dep_context=non-requeueable deps ti=<TaskInstance: import_csv_to_postgres.load_csv_to_postgres scheduled__2025-08-26T15:00:00+00:00 [queued]>
[2025-08-26T15:44:12.026+0000] {taskinstance.py:2076} INFO - Dependencies all met for dep_context=requeueable deps ti=<TaskInstance: import_csv_to_postgres.load_csv_to_postgres scheduled__2025-08-26T15:00:00+00:00 [queued]>
[2025-08-26T15:44:12.026+0000] {taskinstance.py:2306} INFO - Starting attempt 1 of 1
[2025-08-26T15:44:12.041+0000] {taskinstance.py:2330} INFO - Executing <Task(PythonOperator): load_csv_to_postgres> on 2025-08-26 15:00:00+00:00
[2025-08-26T15:44:12.049+0000] {warnings.py:112} WARNING - /home/airflow/.local/lib/python3.12/site-packages/airflow/task/task_runner/standard_task_runner.py:62: DeprecationWarning: This process (pid=1188) is multi-threaded, use of fork() may lead to deadlocks in the child.
  pid = os.fork()

[2025-08-26T15:44:12.050+0000] {standard_task_runner.py:64} INFO - Started process 1190 to run task
[2025-08-26T15:44:12.054+0000] {standard_task_runner.py:90} INFO - Running: ['airflow', 'tasks', 'run', 'import_csv_to_postgres', 'load_csv_to_postgres', 'scheduled__2025-08-26T15:00:00+00:00', '--job-id', '625', '--raw', '--subdir', 'DAGS_FOLDER/csv_to_postgres_dag.py', '--cfg-path', '/tmp/tmpmfjczex2']
[2025-08-26T15:44:12.056+0000] {standard_task_runner.py:91} INFO - Job 625: Subtask load_csv_to_postgres
[2025-08-26T15:44:12.073+0000] {warnings.py:112} WARNING - /home/airflow/.local/lib/python3.12/site-packages/airflow/settings.py:195: DeprecationWarning: The sql_alchemy_conn option in [core] has been moved to the sql_alchemy_conn option in [database] - the old setting has been used, but please update your config.
  SQL_ALCHEMY_CONN = conf.get("database", "SQL_ALCHEMY_CONN")

[2025-08-26T15:44:12.109+0000] {task_command.py:426} INFO - Running <TaskInstance: import_csv_to_postgres.load_csv_to_postgres scheduled__2025-08-26T15:00:00+00:00 [running]> on host b5ea13053d47
[2025-08-26T15:44:12.252+0000] {taskinstance.py:2648} INFO - Exporting env vars: AIRFLOW_CTX_DAG_OWNER='airflow' AIRFLOW_CTX_DAG_ID='import_csv_to_postgres' AIRFLOW_CTX_TASK_ID='load_csv_to_postgres' AIRFLOW_CTX_EXECUTION_DATE='2025-08-26T15:00:00+00:00' AIRFLOW_CTX_TRY_NUMBER='1' AIRFLOW_CTX_DAG_RUN_ID='scheduled__2025-08-26T15:00:00+00:00'
[2025-08-26T15:44:12.254+0000] {taskinstance.py:430} INFO - ::endgroup::
[2025-08-26T15:44:12.290+0000] {base.py:84} INFO - Using connection ID 'postgres_conn' for task execution.
[2025-08-26T15:44:12.698+0000] {logging_mixin.py:188} INFO - âœ… Ð—Ð°Ð³Ñ€ÑƒÐ¶ÐµÐ½ Ñ„Ð°Ð¹Ð» customers.csv Ð² Ñ‚Ð°Ð±Ð»Ð¸Ñ†Ñƒ customers
[2025-08-26T15:44:12.769+0000] {logging_mixin.py:188} INFO - âœ… Ð—Ð°Ð³Ñ€ÑƒÐ¶ÐµÐ½ Ñ„Ð°Ð¹Ð» products.csv Ð² Ñ‚Ð°Ð±Ð»Ð¸Ñ†Ñƒ products
[2025-08-26T15:44:13.320+0000] {logging_mixin.py:188} INFO - âœ… Ð—Ð°Ð³Ñ€ÑƒÐ¶ÐµÐ½ Ñ„Ð°Ð¹Ð» shipments.csv Ð² Ñ‚Ð°Ð±Ð»Ð¸Ñ†Ñƒ shipments
[2025-08-26T15:44:13.675+0000] {taskinstance.py:441} INFO - ::group::Post task execution logs
[2025-08-26T15:44:13.675+0000] {taskinstance.py:2905} ERROR - Task failed with exception
Traceback (most recent call last):
  File "/home/airflow/.local/lib/python3.12/site-packages/sqlalchemy/engine/base.py", line 1890, in _execute_context
    self.dialect.do_executemany(
  File "/home/airflow/.local/lib/python3.12/site-packages/sqlalchemy/dialects/postgresql/psycopg2.py", line 982, in do_executemany
    context._psycopg2_fetched_rows = xtras.execute_values(
                                     ^^^^^^^^^^^^^^^^^^^^^
  File "/home/airflow/.local/lib/python3.12/site-packages/psycopg2/extras.py", line 1299, in execute_values
    cur.execute(b''.join(parts))
psycopg2.errors.UniqueViolation: duplicate key value violates unique constraint "orders_pkey"
DETAIL:  Key (order_id)=(7324) already exists.


The above exception was the direct cause of the following exception:

Traceback (most recent call last):
  File "/home/airflow/.local/lib/python3.12/site-packages/airflow/models/taskinstance.py", line 465, in _execute_task
    result = _execute_callable(context=context, **execute_callable_kwargs)
             ^^^^^^^^^^^^^^^^^^^^^^^^^^^^^^^^^^^^^^^^^^^^^^^^^^^^^^^^^^^^^
  File "/home/airflow/.local/lib/python3.12/site-packages/airflow/models/taskinstance.py", line 432, in _execute_callable
    return execute_callable(context=context, **execute_callable_kwargs)
           ^^^^^^^^^^^^^^^^^^^^^^^^^^^^^^^^^^^^^^^^^^^^^^^^^^^^^^^^^^^^
  File "/home/airflow/.local/lib/python3.12/site-packages/airflow/models/baseoperator.py", line 401, in wrapper
    return func(self, *args, **kwargs)
           ^^^^^^^^^^^^^^^^^^^^^^^^^^^
  File "/home/airflow/.local/lib/python3.12/site-packages/airflow/operators/python.py", line 235, in execute
    return_value = self.execute_callable()
                   ^^^^^^^^^^^^^^^^^^^^^^^
  File "/home/airflow/.local/lib/python3.12/site-packages/airflow/operators/python.py", line 252, in execute_callable
    return self.python_callable(*self.op_args, **self.op_kwargs)
           ^^^^^^^^^^^^^^^^^^^^^^^^^^^^^^^^^^^^^^^^^^^^^^^^^^^^^
  File "/opt/airflow/dags/csv_to_postgres_dag.py", line 74, in load_csv_to_postgres
    df.to_sql(table_name, engine, if_exists="append", index=False, dtype=dtype_mapping)
  File "/home/airflow/.local/lib/python3.12/site-packages/pandas/util/_decorators.py", line 333, in wrapper
    return func(*args, **kwargs)
           ^^^^^^^^^^^^^^^^^^^^^
  File "/home/airflow/.local/lib/python3.12/site-packages/pandas/core/generic.py", line 3008, in to_sql
    return sql.to_sql(
           ^^^^^^^^^^^
  File "/home/airflow/.local/lib/python3.12/site-packages/pandas/io/sql.py", line 788, in to_sql
    return pandas_sql.to_sql(
           ^^^^^^^^^^^^^^^^^^
  File "/home/airflow/.local/lib/python3.12/site-packages/pandas/io/sql.py", line 1958, in to_sql
    total_inserted = sql_engine.insert_records(
                     ^^^^^^^^^^^^^^^^^^^^^^^^^^
  File "/home/airflow/.local/lib/python3.12/site-packages/pandas/io/sql.py", line 1507, in insert_records
    raise err
  File "/home/airflow/.local/lib/python3.12/site-packages/pandas/io/sql.py", line 1498, in insert_records
    return table.insert(chunksize=chunksize, method=method)
           ^^^^^^^^^^^^^^^^^^^^^^^^^^^^^^^^^^^^^^^^^^^^^^^^
  File "/home/airflow/.local/lib/python3.12/site-packages/pandas/io/sql.py", line 1059, in insert
    num_inserted = exec_insert(conn, keys, chunk_iter)
                   ^^^^^^^^^^^^^^^^^^^^^^^^^^^^^^^^^^^
  File "/home/airflow/.local/lib/python3.12/site-packages/pandas/io/sql.py", line 951, in _execute_insert
    result = conn.execute(self.table.insert(), data)
             ^^^^^^^^^^^^^^^^^^^^^^^^^^^^^^^^^^^^^^^
  File "/home/airflow/.local/lib/python3.12/site-packages/sqlalchemy/engine/base.py", line 1385, in execute
    return meth(self, multiparams, params, _EMPTY_EXECUTION_OPTS)
           ^^^^^^^^^^^^^^^^^^^^^^^^^^^^^^^^^^^^^^^^^^^^^^^^^^^^^^
  File "/home/airflow/.local/lib/python3.12/site-packages/sqlalchemy/sql/elements.py", line 334, in _execute_on_connection
    return connection._execute_clauseelement(
           ^^^^^^^^^^^^^^^^^^^^^^^^^^^^^^^^^^
  File "/home/airflow/.local/lib/python3.12/site-packages/sqlalchemy/engine/base.py", line 1577, in _execute_clauseelement
    ret = self._execute_context(
          ^^^^^^^^^^^^^^^^^^^^^^
  File "/home/airflow/.local/lib/python3.12/site-packages/sqlalchemy/engine/base.py", line 1953, in _execute_context
    self._handle_dbapi_exception(
  File "/home/airflow/.local/lib/python3.12/site-packages/sqlalchemy/engine/base.py", line 2134, in _handle_dbapi_exception
    util.raise_(
  File "/home/airflow/.local/lib/python3.12/site-packages/sqlalchemy/util/compat.py", line 211, in raise_
    raise exception
  File "/home/airflow/.local/lib/python3.12/site-packages/sqlalchemy/engine/base.py", line 1890, in _execute_context
    self.dialect.do_executemany(
  File "/home/airflow/.local/lib/python3.12/site-packages/sqlalchemy/dialects/postgresql/psycopg2.py", line 982, in do_executemany
    context._psycopg2_fetched_rows = xtras.execute_values(
                                     ^^^^^^^^^^^^^^^^^^^^^
  File "/home/airflow/.local/lib/python3.12/site-packages/psycopg2/extras.py", line 1299, in execute_values
    cur.execute(b''.join(parts))
sqlalchemy.exc.IntegrityError: (psycopg2.errors.UniqueViolation) duplicate key value violates unique constraint "orders_pkey"
DETAIL:  Key (order_id)=(7324) already exists.

[SQL: INSERT INTO orders (order_id, order_date, customer_id, total_price, status) VALUES (%(order_id)s, %(order_date)s, %(customer_id)s, %(total_price)s, %(status)s)]
[parameters: ({'order_id': 7324, 'order_date': '2023-11-27', 'customer_id': 2160, 'total_price': 955.86, 'status': 'shipped'}, {'order_id': 8938, 'order_date': '2024-08-31', 'customer_id': 8497, 'total_price': 984.91, 'status': 'delivered'}, {'order_id': 4238, 'order_date': '2023-12-05', 'customer_id': 6295, 'total_price': 649.18, 'status': 'delivered'}, {'order_id': 10944, 'order_date': '2024-02-22', 'customer_id': 2936, 'total_price': 54.83, 'status': 'delivered'}, {'order_id': 11075, 'order_date': '2024-08-14', 'customer_id': 2994, 'total_price': 320.24, 'status': 'pending'}, {'order_id': 13842, 'order_date': '2024-05-20', 'customer_id': 5953, 'total_price': 555.05, 'status': 'shipped'}, {'order_id': 1126, 'order_date': '2023-11-17', 'customer_id': 4825, 'total_price': 308.21, 'status': 'shipped'}, {'order_id': 8310, 'order_date': '2024-08-09', 'customer_id': 7873, 'total_price': 957.72, 'status': 'delivered'}  ... displaying 10 of 15026 total bound parameter sets ...  {'order_id': 15025, 'order_date': '2024-11-29 00:00:00', 'customer_id': 4093, 'total_price': None, 'status': 'shipped'}, {'order_id': 15026, 'order_date': '2024-11-30 00:00:00', 'customer_id': 4093, 'total_price': None, 'status': 'shipped'})]
(Background on this error at: https://sqlalche.me/e/14/gkpj)
[2025-08-26T15:44:13.690+0000] {taskinstance.py:1206} INFO - Marking task as FAILED. dag_id=import_csv_to_postgres, task_id=load_csv_to_postgres, run_id=scheduled__2025-08-26T15:00:00+00:00, execution_date=20250826T150000, start_date=20250826T154412, end_date=20250826T154413
[2025-08-26T15:44:13.713+0000] {standard_task_runner.py:110} ERROR - Failed to execute job 625 for task load_csv_to_postgres ((psycopg2.errors.UniqueViolation) duplicate key value violates unique constraint "orders_pkey"
DETAIL:  Key (order_id)=(7324) already exists.

[SQL: INSERT INTO orders (order_id, order_date, customer_id, total_price, status) VALUES (%(order_id)s, %(order_date)s, %(customer_id)s, %(total_price)s, %(status)s)]
[parameters: ({'order_id': 7324, 'order_date': '2023-11-27', 'customer_id': 2160, 'total_price': 955.86, 'status': 'shipped'}, {'order_id': 8938, 'order_date': '2024-08-31', 'customer_id': 8497, 'total_price': 984.91, 'status': 'delivered'}, {'order_id': 4238, 'order_date': '2023-12-05', 'customer_id': 6295, 'total_price': 649.18, 'status': 'delivered'}, {'order_id': 10944, 'order_date': '2024-02-22', 'customer_id': 2936, 'total_price': 54.83, 'status': 'delivered'}, {'order_id': 11075, 'order_date': '2024-08-14', 'customer_id': 2994, 'total_price': 320.24, 'status': 'pending'}, {'order_id': 13842, 'order_date': '2024-05-20', 'customer_id': 5953, 'total_price': 555.05, 'status': 'shipped'}, {'order_id': 1126, 'order_date': '2023-11-17', 'customer_id': 4825, 'total_price': 308.21, 'status': 'shipped'}, {'order_id': 8310, 'order_date': '2024-08-09', 'customer_id': 7873, 'total_price': 957.72, 'status': 'delivered'}  ... displaying 10 of 15026 total bound parameter sets ...  {'order_id': 15025, 'order_date': '2024-11-29 00:00:00', 'customer_id': 4093, 'total_price': None, 'status': 'shipped'}, {'order_id': 15026, 'order_date': '2024-11-30 00:00:00', 'customer_id': 4093, 'total_price': None, 'status': 'shipped'})]
(Background on this error at: https://sqlalche.me/e/14/gkpj); 1190)
[2025-08-26T15:44:13.749+0000] {local_task_job_runner.py:243} INFO - Task exited with return code 1
[2025-08-26T15:44:13.768+0000] {taskinstance.py:3503} INFO - 0 downstream tasks scheduled from follow-on schedule check
[2025-08-26T15:44:13.771+0000] {local_task_job_runner.py:222} INFO - ::endgroup::
[2025-08-26T15:53:14.606+0000] {local_task_job_runner.py:120} INFO - ::group::Pre task execution logs
[2025-08-26T15:53:14.659+0000] {taskinstance.py:2076} INFO - Dependencies all met for dep_context=non-requeueable deps ti=<TaskInstance: import_csv_to_postgres.load_csv_to_postgres scheduled__2025-08-26T15:00:00+00:00 [queued]>
[2025-08-26T15:53:14.677+0000] {taskinstance.py:2076} INFO - Dependencies all met for dep_context=requeueable deps ti=<TaskInstance: import_csv_to_postgres.load_csv_to_postgres scheduled__2025-08-26T15:00:00+00:00 [queued]>
[2025-08-26T15:53:14.678+0000] {taskinstance.py:2306} INFO - Starting attempt 1 of 1
[2025-08-26T15:53:14.711+0000] {taskinstance.py:2330} INFO - Executing <Task(PythonOperator): load_csv_to_postgres> on 2025-08-26 15:00:00+00:00
[2025-08-26T15:53:14.722+0000] {warnings.py:112} WARNING - /home/airflow/.local/lib/python3.12/site-packages/airflow/task/task_runner/standard_task_runner.py:62: DeprecationWarning: This process (pid=1194) is multi-threaded, use of fork() may lead to deadlocks in the child.
  pid = os.fork()

[2025-08-26T15:53:14.724+0000] {standard_task_runner.py:64} INFO - Started process 1196 to run task
[2025-08-26T15:53:14.731+0000] {standard_task_runner.py:90} INFO - Running: ['airflow', 'tasks', 'run', 'import_csv_to_postgres', 'load_csv_to_postgres', 'scheduled__2025-08-26T15:00:00+00:00', '--job-id', '627', '--raw', '--subdir', 'DAGS_FOLDER/csv_to_postgres_dag.py', '--cfg-path', '/tmp/tmpo67q906r']
[2025-08-26T15:53:14.735+0000] {standard_task_runner.py:91} INFO - Job 627: Subtask load_csv_to_postgres
[2025-08-26T15:53:14.758+0000] {warnings.py:112} WARNING - /home/airflow/.local/lib/python3.12/site-packages/airflow/settings.py:195: DeprecationWarning: The sql_alchemy_conn option in [core] has been moved to the sql_alchemy_conn option in [database] - the old setting has been used, but please update your config.
  SQL_ALCHEMY_CONN = conf.get("database", "SQL_ALCHEMY_CONN")

[2025-08-26T15:53:14.811+0000] {task_command.py:426} INFO - Running <TaskInstance: import_csv_to_postgres.load_csv_to_postgres scheduled__2025-08-26T15:00:00+00:00 [running]> on host b5ea13053d47
[2025-08-26T15:53:14.979+0000] {taskinstance.py:2648} INFO - Exporting env vars: AIRFLOW_CTX_DAG_OWNER='airflow' AIRFLOW_CTX_DAG_ID='import_csv_to_postgres' AIRFLOW_CTX_TASK_ID='load_csv_to_postgres' AIRFLOW_CTX_EXECUTION_DATE='2025-08-26T15:00:00+00:00' AIRFLOW_CTX_TRY_NUMBER='1' AIRFLOW_CTX_DAG_RUN_ID='scheduled__2025-08-26T15:00:00+00:00'
[2025-08-26T15:53:14.980+0000] {taskinstance.py:430} INFO - ::endgroup::
[2025-08-26T15:53:15.013+0000] {base.py:84} INFO - Using connection ID 'postgres_conn' for task execution.
[2025-08-26T15:53:15.026+0000] {logging_mixin.py:188} INFO - ðŸ—‘ Ð¢Ð°Ð±Ð»Ð¸Ñ†Ð° order_items Ð¾Ñ‡Ð¸Ñ‰ÐµÐ½Ð°
[2025-08-26T15:53:15.045+0000] {logging_mixin.py:188} INFO - ðŸ—‘ Ð¢Ð°Ð±Ð»Ð¸Ñ†Ð° payment Ð¾Ñ‡Ð¸Ñ‰ÐµÐ½Ð°
[2025-08-26T15:53:15.073+0000] {logging_mixin.py:188} INFO - ðŸ—‘ Ð¢Ð°Ð±Ð»Ð¸Ñ†Ð° orders Ð¾Ñ‡Ð¸Ñ‰ÐµÐ½Ð°
[2025-08-26T15:53:15.085+0000] {logging_mixin.py:188} INFO - ðŸ—‘ Ð¢Ð°Ð±Ð»Ð¸Ñ†Ð° shipments Ð¾Ñ‡Ð¸Ñ‰ÐµÐ½Ð°
[2025-08-26T15:53:15.096+0000] {logging_mixin.py:188} INFO - ðŸ—‘ Ð¢Ð°Ð±Ð»Ð¸Ñ†Ð° customers Ð¾Ñ‡Ð¸Ñ‰ÐµÐ½Ð°
[2025-08-26T15:53:15.103+0000] {logging_mixin.py:188} INFO - ðŸ—‘ Ð¢Ð°Ð±Ð»Ð¸Ñ†Ð° products Ð¾Ñ‡Ð¸Ñ‰ÐµÐ½Ð°
[2025-08-26T15:53:15.112+0000] {logging_mixin.py:188} INFO - ðŸ—‘ Ð¢Ð°Ð±Ð»Ð¸Ñ†Ð° suppliers Ð¾Ñ‡Ð¸Ñ‰ÐµÐ½Ð°
[2025-08-26T15:53:15.688+0000] {logging_mixin.py:188} INFO - âœ… Ð—Ð°Ð³Ñ€ÑƒÐ¶ÐµÐ½ Ñ„Ð°Ð¹Ð» customers.csv Ð² Ñ‚Ð°Ð±Ð»Ð¸Ñ†Ñƒ customers
[2025-08-26T15:53:15.772+0000] {logging_mixin.py:188} INFO - âœ… Ð—Ð°Ð³Ñ€ÑƒÐ¶ÐµÐ½ Ñ„Ð°Ð¹Ð» products.csv Ð² Ñ‚Ð°Ð±Ð»Ð¸Ñ†Ñƒ products
[2025-08-26T15:53:16.267+0000] {logging_mixin.py:188} INFO - âœ… Ð—Ð°Ð³Ñ€ÑƒÐ¶ÐµÐ½ Ñ„Ð°Ð¹Ð» shipments.csv Ð² Ñ‚Ð°Ð±Ð»Ð¸Ñ†Ñƒ shipments
[2025-08-26T15:53:16.883+0000] {logging_mixin.py:188} INFO - âœ… Ð—Ð°Ð³Ñ€ÑƒÐ¶ÐµÐ½ Ñ„Ð°Ð¹Ð» orders.csv Ð² Ñ‚Ð°Ð±Ð»Ð¸Ñ†Ñƒ orders
[2025-08-26T15:53:17.454+0000] {logging_mixin.py:188} INFO - âœ… Ð—Ð°Ð³Ñ€ÑƒÐ¶ÐµÐ½ Ñ„Ð°Ð¹Ð» order_items.csv Ð² Ñ‚Ð°Ð±Ð»Ð¸Ñ†Ñƒ order_items
[2025-08-26T15:53:17.454+0000] {python.py:237} INFO - Done. Returned value was: None
[2025-08-26T15:53:17.454+0000] {taskinstance.py:441} INFO - ::group::Post task execution logs
[2025-08-26T15:53:17.463+0000] {taskinstance.py:1206} INFO - Marking task as SUCCESS. dag_id=import_csv_to_postgres, task_id=load_csv_to_postgres, run_id=scheduled__2025-08-26T15:00:00+00:00, execution_date=20250826T150000, start_date=20250826T155314, end_date=20250826T155317
[2025-08-26T15:53:17.515+0000] {local_task_job_runner.py:243} INFO - Task exited with return code 0
[2025-08-26T15:53:17.545+0000] {taskinstance.py:3503} INFO - 0 downstream tasks scheduled from follow-on schedule check
[2025-08-26T15:53:17.549+0000] {local_task_job_runner.py:222} INFO - ::endgroup::
