[2025-08-21T23:00:02.422+0000] {local_task_job_runner.py:120} INFO - ::group::Pre task execution logs
[2025-08-21T23:00:02.446+0000] {taskinstance.py:2076} INFO - Dependencies all met for dep_context=non-requeueable deps ti=<TaskInstance: daily_generate_orders.generate_new_data scheduled__2025-08-21T22:00:00+00:00 [queued]>
[2025-08-21T23:00:02.454+0000] {taskinstance.py:2076} INFO - Dependencies all met for dep_context=requeueable deps ti=<TaskInstance: daily_generate_orders.generate_new_data scheduled__2025-08-21T22:00:00+00:00 [queued]>
[2025-08-21T23:00:02.454+0000] {taskinstance.py:2306} INFO - Starting attempt 1 of 1
[2025-08-21T23:00:02.470+0000] {taskinstance.py:2330} INFO - Executing <Task(PythonOperator): generate_new_data> on 2025-08-21 22:00:00+00:00
[2025-08-21T23:00:02.478+0000] {warnings.py:112} WARNING - /home/airflow/.local/lib/python3.12/site-packages/airflow/task/task_runner/standard_task_runner.py:62: DeprecationWarning: This process (pid=246) is multi-threaded, use of fork() may lead to deadlocks in the child.
  pid = os.fork()

[2025-08-21T23:00:02.479+0000] {standard_task_runner.py:64} INFO - Started process 250 to run task
[2025-08-21T23:00:02.482+0000] {standard_task_runner.py:90} INFO - Running: ['airflow', 'tasks', 'run', 'daily_generate_orders', 'generate_new_data', 'scheduled__2025-08-21T22:00:00+00:00', '--job-id', '116', '--raw', '--subdir', 'DAGS_FOLDER/generate_fake_shop_csv.py', '--cfg-path', '/tmp/tmpt700dc9m']
[2025-08-21T23:00:02.485+0000] {standard_task_runner.py:91} INFO - Job 116: Subtask generate_new_data
[2025-08-21T23:00:02.498+0000] {warnings.py:112} WARNING - /home/airflow/.local/lib/python3.12/site-packages/airflow/settings.py:195: DeprecationWarning: The sql_alchemy_conn option in [core] has been moved to the sql_alchemy_conn option in [database] - the old setting has been used, but please update your config.
  SQL_ALCHEMY_CONN = conf.get("database", "SQL_ALCHEMY_CONN")

[2025-08-21T23:00:02.543+0000] {task_command.py:426} INFO - Running <TaskInstance: daily_generate_orders.generate_new_data scheduled__2025-08-21T22:00:00+00:00 [running]> on host 71579c071e19
[2025-08-21T23:00:02.652+0000] {taskinstance.py:2648} INFO - Exporting env vars: AIRFLOW_CTX_DAG_OWNER='airflow' AIRFLOW_CTX_DAG_ID='daily_generate_orders' AIRFLOW_CTX_TASK_ID='generate_new_data' AIRFLOW_CTX_EXECUTION_DATE='2025-08-21T22:00:00+00:00' AIRFLOW_CTX_TRY_NUMBER='1' AIRFLOW_CTX_DAG_RUN_ID='scheduled__2025-08-21T22:00:00+00:00'
[2025-08-21T23:00:02.653+0000] {taskinstance.py:430} INFO - ::endgroup::
[2025-08-21T23:00:02.719+0000] {taskinstance.py:441} INFO - ::group::Post task execution logs
[2025-08-21T23:00:02.719+0000] {taskinstance.py:2905} ERROR - Task failed with exception
Traceback (most recent call last):
  File "/home/airflow/.local/lib/python3.12/site-packages/airflow/models/taskinstance.py", line 465, in _execute_task
    result = _execute_callable(context=context, **execute_callable_kwargs)
             ^^^^^^^^^^^^^^^^^^^^^^^^^^^^^^^^^^^^^^^^^^^^^^^^^^^^^^^^^^^^^
  File "/home/airflow/.local/lib/python3.12/site-packages/airflow/models/taskinstance.py", line 432, in _execute_callable
    return execute_callable(context=context, **execute_callable_kwargs)
           ^^^^^^^^^^^^^^^^^^^^^^^^^^^^^^^^^^^^^^^^^^^^^^^^^^^^^^^^^^^^
  File "/home/airflow/.local/lib/python3.12/site-packages/airflow/models/baseoperator.py", line 401, in wrapper
    return func(self, *args, **kwargs)
           ^^^^^^^^^^^^^^^^^^^^^^^^^^^
  File "/home/airflow/.local/lib/python3.12/site-packages/airflow/operators/python.py", line 235, in execute
    return_value = self.execute_callable()
                   ^^^^^^^^^^^^^^^^^^^^^^^
  File "/home/airflow/.local/lib/python3.12/site-packages/airflow/operators/python.py", line 252, in execute_callable
    return self.python_callable(*self.op_args, **self.op_kwargs)
           ^^^^^^^^^^^^^^^^^^^^^^^^^^^^^^^^^^^^^^^^^^^^^^^^^^^^^
  File "/opt/airflow/dags/generate_fake_shop_csv.py", line 57, in generate_new_data
    payments, payments_types = read_csv_with_types("payments.csv")
                               ^^^^^^^^^^^^^^^^^^^^^^^^^^^^^^^^^^^
  File "/opt/airflow/dags/generate_fake_shop_csv.py", line 34, in read_csv_with_types
    df = pd.read_csv(file_path)
         ^^^^^^^^^^^^^^^^^^^^^^
  File "/home/airflow/.local/lib/python3.12/site-packages/pandas/io/parsers/readers.py", line 948, in read_csv
    return _read(filepath_or_buffer, kwds)
           ^^^^^^^^^^^^^^^^^^^^^^^^^^^^^^^
  File "/home/airflow/.local/lib/python3.12/site-packages/pandas/io/parsers/readers.py", line 611, in _read
    parser = TextFileReader(filepath_or_buffer, **kwds)
             ^^^^^^^^^^^^^^^^^^^^^^^^^^^^^^^^^^^^^^^^^^
  File "/home/airflow/.local/lib/python3.12/site-packages/pandas/io/parsers/readers.py", line 1448, in __init__
    self._engine = self._make_engine(f, self.engine)
                   ^^^^^^^^^^^^^^^^^^^^^^^^^^^^^^^^^
  File "/home/airflow/.local/lib/python3.12/site-packages/pandas/io/parsers/readers.py", line 1705, in _make_engine
    self.handles = get_handle(
                   ^^^^^^^^^^^
  File "/home/airflow/.local/lib/python3.12/site-packages/pandas/io/common.py", line 863, in get_handle
    handle = open(
             ^^^^^
FileNotFoundError: [Errno 2] No such file or directory: '/opt/airflow/plugins/payments.csv'
[2025-08-21T23:00:02.730+0000] {taskinstance.py:1206} INFO - Marking task as FAILED. dag_id=daily_generate_orders, task_id=generate_new_data, run_id=scheduled__2025-08-21T22:00:00+00:00, execution_date=20250821T220000, start_date=20250821T230002, end_date=20250821T230002
[2025-08-21T23:00:02.746+0000] {standard_task_runner.py:110} ERROR - Failed to execute job 116 for task generate_new_data ([Errno 2] No such file or directory: '/opt/airflow/plugins/payments.csv'; 250)
[2025-08-21T23:00:02.779+0000] {local_task_job_runner.py:243} INFO - Task exited with return code 1
[2025-08-21T23:00:02.800+0000] {taskinstance.py:3503} INFO - 0 downstream tasks scheduled from follow-on schedule check
[2025-08-21T23:00:02.808+0000] {local_task_job_runner.py:222} INFO - ::endgroup::
