[2025-08-25T08:47:29.298+0000] {local_task_job_runner.py:120} INFO - ::group::Pre task execution logs
[2025-08-25T08:47:29.418+0000] {taskinstance.py:2076} INFO - Dependencies all met for dep_context=non-requeueable deps ti=<TaskInstance: dbt_run_models.run_dbt_models scheduled__2025-08-24T06:00:00+00:00 [queued]>
[2025-08-25T08:47:29.458+0000] {taskinstance.py:2076} INFO - Dependencies all met for dep_context=requeueable deps ti=<TaskInstance: dbt_run_models.run_dbt_models scheduled__2025-08-24T06:00:00+00:00 [queued]>
[2025-08-25T08:47:29.458+0000] {taskinstance.py:2306} INFO - Starting attempt 3 of 4
[2025-08-25T08:47:29.483+0000] {taskinstance.py:2330} INFO - Executing <Task(BashOperator): run_dbt_models> on 2025-08-24 06:00:00+00:00
[2025-08-25T08:47:29.495+0000] {warnings.py:112} WARNING - /home/airflow/.local/lib/python3.12/site-packages/airflow/task/task_runner/standard_task_runner.py:62: DeprecationWarning: This process (pid=69) is multi-threaded, use of fork() may lead to deadlocks in the child.
  pid = os.fork()

[2025-08-25T08:47:29.497+0000] {standard_task_runner.py:64} INFO - Started process 73 to run task
[2025-08-25T08:47:29.508+0000] {standard_task_runner.py:90} INFO - Running: ['airflow', 'tasks', 'run', 'dbt_run_models', 'run_dbt_models', 'scheduled__2025-08-24T06:00:00+00:00', '--job-id', '458', '--raw', '--subdir', 'DAGS_FOLDER/dbt_dag.py', '--cfg-path', '/tmp/tmp2p33pk4q']
[2025-08-25T08:47:29.509+0000] {standard_task_runner.py:91} INFO - Job 458: Subtask run_dbt_models
[2025-08-25T08:47:29.539+0000] {warnings.py:112} WARNING - /home/airflow/.local/lib/python3.12/site-packages/airflow/settings.py:195: DeprecationWarning: The sql_alchemy_conn option in [core] has been moved to the sql_alchemy_conn option in [database] - the old setting has been used, but please update your config.
  SQL_ALCHEMY_CONN = conf.get("database", "SQL_ALCHEMY_CONN")

[2025-08-25T08:47:29.621+0000] {task_command.py:426} INFO - Running <TaskInstance: dbt_run_models.run_dbt_models scheduled__2025-08-24T06:00:00+00:00 [running]> on host b71dcd990cf2
[2025-08-25T08:47:29.905+0000] {taskinstance.py:2648} INFO - Exporting env vars: AIRFLOW_CTX_DAG_OWNER='airflow' AIRFLOW_CTX_DAG_ID='dbt_run_models' AIRFLOW_CTX_TASK_ID='run_dbt_models' AIRFLOW_CTX_EXECUTION_DATE='2025-08-24T06:00:00+00:00' AIRFLOW_CTX_TRY_NUMBER='3' AIRFLOW_CTX_DAG_RUN_ID='scheduled__2025-08-24T06:00:00+00:00'
[2025-08-25T08:47:29.909+0000] {taskinstance.py:430} INFO - ::endgroup::
[2025-08-25T08:47:29.964+0000] {subprocess.py:63} INFO - Tmp dir root location: /tmp
[2025-08-25T08:47:29.964+0000] {subprocess.py:75} INFO - Running command: ['/usr/bin/bash', '-c', '\n        cd /usr/app &&         dbt run --profiles-dir /usr/app\n        ']
[2025-08-25T08:47:29.980+0000] {subprocess.py:86} INFO - Output:
[2025-08-25T08:47:41.331+0000] {subprocess.py:93} INFO - [0m08:47:41  Running with dbt=1.7.9
[2025-08-25T08:47:41.348+0000] {subprocess.py:93} INFO - [0m08:47:41  Encountered an error:
[2025-08-25T08:47:41.348+0000] {subprocess.py:93} INFO - Runtime Error
[2025-08-25T08:47:41.348+0000] {subprocess.py:93} INFO -   Could not find profile named 'default'
[2025-08-25T08:47:42.629+0000] {subprocess.py:97} INFO - Command exited with return code 2
[2025-08-25T08:47:42.631+0000] {taskinstance.py:441} INFO - ::group::Post task execution logs
[2025-08-25T08:47:42.643+0000] {taskinstance.py:2905} ERROR - Task failed with exception
Traceback (most recent call last):
  File "/home/airflow/.local/lib/python3.12/site-packages/airflow/models/taskinstance.py", line 465, in _execute_task
    result = _execute_callable(context=context, **execute_callable_kwargs)
             ^^^^^^^^^^^^^^^^^^^^^^^^^^^^^^^^^^^^^^^^^^^^^^^^^^^^^^^^^^^^^
  File "/home/airflow/.local/lib/python3.12/site-packages/airflow/models/taskinstance.py", line 432, in _execute_callable
    return execute_callable(context=context, **execute_callable_kwargs)
           ^^^^^^^^^^^^^^^^^^^^^^^^^^^^^^^^^^^^^^^^^^^^^^^^^^^^^^^^^^^^
  File "/home/airflow/.local/lib/python3.12/site-packages/airflow/models/baseoperator.py", line 401, in wrapper
    return func(self, *args, **kwargs)
           ^^^^^^^^^^^^^^^^^^^^^^^^^^^
  File "/home/airflow/.local/lib/python3.12/site-packages/airflow/operators/bash.py", line 243, in execute
    raise AirflowException(
airflow.exceptions.AirflowException: Bash command failed. The command returned a non-zero exit code 2.
[2025-08-25T08:47:42.665+0000] {taskinstance.py:1206} INFO - Marking task as UP_FOR_RETRY. dag_id=dbt_run_models, task_id=run_dbt_models, run_id=scheduled__2025-08-24T06:00:00+00:00, execution_date=20250824T060000, start_date=20250825T084729, end_date=20250825T084742
[2025-08-25T08:47:42.695+0000] {standard_task_runner.py:110} ERROR - Failed to execute job 458 for task run_dbt_models (Bash command failed. The command returned a non-zero exit code 2.; 73)
[2025-08-25T08:47:42.749+0000] {local_task_job_runner.py:243} INFO - Task exited with return code 1
[2025-08-25T08:47:42.802+0000] {taskinstance.py:3503} INFO - 0 downstream tasks scheduled from follow-on schedule check
[2025-08-25T08:47:42.807+0000] {local_task_job_runner.py:222} INFO - ::endgroup::
