[2025-08-26T13:35:53.100+0000] {local_task_job_runner.py:120} INFO - ::group::Pre task execution logs
[2025-08-26T13:35:53.149+0000] {taskinstance.py:2076} INFO - Dependencies all met for dep_context=non-requeueable deps ti=<TaskInstance: import_csv_to_postgres.load_csv_to_postgres manual__2025-08-26T13:35:51.540848+00:00 [queued]>
[2025-08-26T13:35:53.168+0000] {taskinstance.py:2076} INFO - Dependencies all met for dep_context=requeueable deps ti=<TaskInstance: import_csv_to_postgres.load_csv_to_postgres manual__2025-08-26T13:35:51.540848+00:00 [queued]>
[2025-08-26T13:35:53.169+0000] {taskinstance.py:2306} INFO - Starting attempt 1 of 1
[2025-08-26T13:35:53.209+0000] {taskinstance.py:2330} INFO - Executing <Task(PythonOperator): load_csv_to_postgres> on 2025-08-26 13:35:51.540848+00:00
[2025-08-26T13:35:53.221+0000] {warnings.py:112} WARNING - /home/airflow/.local/lib/python3.12/site-packages/airflow/task/task_runner/standard_task_runner.py:62: DeprecationWarning: This process (pid=1145) is multi-threaded, use of fork() may lead to deadlocks in the child.
  pid = os.fork()

[2025-08-26T13:35:53.223+0000] {standard_task_runner.py:64} INFO - Started process 1147 to run task
[2025-08-26T13:35:53.222+0000] {standard_task_runner.py:90} INFO - Running: ['airflow', 'tasks', 'run', 'import_csv_to_postgres', 'load_csv_to_postgres', 'manual__2025-08-26T13:35:51.540848+00:00', '--job-id', '615', '--raw', '--subdir', 'DAGS_FOLDER/csv_to_postgres_dag.py', '--cfg-path', '/tmp/tmpy5doo8ik']
[2025-08-26T13:35:53.224+0000] {standard_task_runner.py:91} INFO - Job 615: Subtask load_csv_to_postgres
[2025-08-26T13:35:53.241+0000] {warnings.py:112} WARNING - /home/airflow/.local/lib/python3.12/site-packages/airflow/settings.py:195: DeprecationWarning: The sql_alchemy_conn option in [core] has been moved to the sql_alchemy_conn option in [database] - the old setting has been used, but please update your config.
  SQL_ALCHEMY_CONN = conf.get("database", "SQL_ALCHEMY_CONN")

[2025-08-26T13:35:53.277+0000] {task_command.py:426} INFO - Running <TaskInstance: import_csv_to_postgres.load_csv_to_postgres manual__2025-08-26T13:35:51.540848+00:00 [running]> on host b5ea13053d47
[2025-08-26T13:35:53.379+0000] {taskinstance.py:2648} INFO - Exporting env vars: AIRFLOW_CTX_DAG_OWNER='airflow' AIRFLOW_CTX_DAG_ID='import_csv_to_postgres' AIRFLOW_CTX_TASK_ID='load_csv_to_postgres' AIRFLOW_CTX_EXECUTION_DATE='2025-08-26T13:35:51.540848+00:00' AIRFLOW_CTX_TRY_NUMBER='1' AIRFLOW_CTX_DAG_RUN_ID='manual__2025-08-26T13:35:51.540848+00:00'
[2025-08-26T13:35:53.380+0000] {taskinstance.py:430} INFO - ::endgroup::
[2025-08-26T13:35:53.403+0000] {base.py:84} INFO - Using connection ID 'postgres_conn' for task execution.
[2025-08-26T13:35:53.459+0000] {logging_mixin.py:188} INFO - üóë –û—á–∏—Å—Ç–∫–∞ —Ç–∞–±–ª–∏—Ü—ã shipments
[2025-08-26T13:35:54.323+0000] {logging_mixin.py:188} INFO - ‚úÖ –ó–∞–≥—Ä—É–∂–µ–Ω —Ñ–∞–π–ª shipments.csv –≤ —Ç–∞–±–ª–∏—Ü—É shipments
[2025-08-26T13:35:54.462+0000] {logging_mixin.py:188} INFO - üóë –û—á–∏—Å—Ç–∫–∞ —Ç–∞–±–ª–∏—Ü—ã customers
[2025-08-26T13:35:54.973+0000] {logging_mixin.py:188} INFO - ‚úÖ –ó–∞–≥—Ä—É–∂–µ–Ω —Ñ–∞–π–ª customers.csv –≤ —Ç–∞–±–ª–∏—Ü—É customers
[2025-08-26T13:35:55.034+0000] {logging_mixin.py:188} INFO - üóë –û—á–∏—Å—Ç–∫–∞ —Ç–∞–±–ª–∏—Ü—ã orders
[2025-08-26T13:35:55.919+0000] {logging_mixin.py:188} INFO - ‚úÖ –ó–∞–≥—Ä—É–∂–µ–Ω —Ñ–∞–π–ª orders.csv –≤ —Ç–∞–±–ª–∏—Ü—É orders
[2025-08-26T13:35:55.937+0000] {logging_mixin.py:188} INFO - üóë –û—á–∏—Å—Ç–∫–∞ —Ç–∞–±–ª–∏—Ü—ã products
[2025-08-26T13:35:55.997+0000] {logging_mixin.py:188} INFO - ‚úÖ –ó–∞–≥—Ä—É–∂–µ–Ω —Ñ–∞–π–ª products.csv –≤ —Ç–∞–±–ª–∏—Ü—É products
[2025-08-26T13:35:56.011+0000] {logging_mixin.py:188} INFO - ‚ûï –î–æ–±–∞–≤–ª–µ–Ω —Å—Ç–æ–ª–±–µ—Ü price_at_purchase –≤ order_items
[2025-08-26T13:35:56.024+0000] {logging_mixin.py:188} INFO - üóë –û—á–∏—Å—Ç–∫–∞ —Ç–∞–±–ª–∏—Ü—ã order_items
[2025-08-26T13:35:57.227+0000] {taskinstance.py:441} INFO - ::group::Post task execution logs
[2025-08-26T13:35:57.228+0000] {taskinstance.py:2905} ERROR - Task failed with exception
Traceback (most recent call last):
  File "/home/airflow/.local/lib/python3.12/site-packages/sqlalchemy/engine/base.py", line 1890, in _execute_context
    self.dialect.do_executemany(
  File "/home/airflow/.local/lib/python3.12/site-packages/sqlalchemy/dialects/postgresql/psycopg2.py", line 982, in do_executemany
    context._psycopg2_fetched_rows = xtras.execute_values(
                                     ^^^^^^^^^^^^^^^^^^^^^
  File "/home/airflow/.local/lib/python3.12/site-packages/psycopg2/extras.py", line 1299, in execute_values
    cur.execute(b''.join(parts))
psycopg2.errors.UniqueViolation: duplicate key value violates unique constraint "order_items_pkey"
DETAIL:  Key (order_item_id)=(20001) already exists.


The above exception was the direct cause of the following exception:

Traceback (most recent call last):
  File "/home/airflow/.local/lib/python3.12/site-packages/airflow/models/taskinstance.py", line 465, in _execute_task
    result = _execute_callable(context=context, **execute_callable_kwargs)
             ^^^^^^^^^^^^^^^^^^^^^^^^^^^^^^^^^^^^^^^^^^^^^^^^^^^^^^^^^^^^^
  File "/home/airflow/.local/lib/python3.12/site-packages/airflow/models/taskinstance.py", line 432, in _execute_callable
    return execute_callable(context=context, **execute_callable_kwargs)
           ^^^^^^^^^^^^^^^^^^^^^^^^^^^^^^^^^^^^^^^^^^^^^^^^^^^^^^^^^^^^
  File "/home/airflow/.local/lib/python3.12/site-packages/airflow/models/baseoperator.py", line 401, in wrapper
    return func(self, *args, **kwargs)
           ^^^^^^^^^^^^^^^^^^^^^^^^^^^
  File "/home/airflow/.local/lib/python3.12/site-packages/airflow/operators/python.py", line 235, in execute
    return_value = self.execute_callable()
                   ^^^^^^^^^^^^^^^^^^^^^^^
  File "/home/airflow/.local/lib/python3.12/site-packages/airflow/operators/python.py", line 252, in execute_callable
    return self.python_callable(*self.op_args, **self.op_kwargs)
           ^^^^^^^^^^^^^^^^^^^^^^^^^^^^^^^^^^^^^^^^^^^^^^^^^^^^^
  File "/opt/airflow/dags/csv_to_postgres_dag.py", line 68, in load_csv_to_postgres
    df.to_sql(table_name, engine, if_exists="append", index=False, dtype=dtype_mapping)
  File "/home/airflow/.local/lib/python3.12/site-packages/pandas/util/_decorators.py", line 333, in wrapper
    return func(*args, **kwargs)
           ^^^^^^^^^^^^^^^^^^^^^
  File "/home/airflow/.local/lib/python3.12/site-packages/pandas/core/generic.py", line 3008, in to_sql
    return sql.to_sql(
           ^^^^^^^^^^^
  File "/home/airflow/.local/lib/python3.12/site-packages/pandas/io/sql.py", line 788, in to_sql
    return pandas_sql.to_sql(
           ^^^^^^^^^^^^^^^^^^
  File "/home/airflow/.local/lib/python3.12/site-packages/pandas/io/sql.py", line 1958, in to_sql
    total_inserted = sql_engine.insert_records(
                     ^^^^^^^^^^^^^^^^^^^^^^^^^^
  File "/home/airflow/.local/lib/python3.12/site-packages/pandas/io/sql.py", line 1507, in insert_records
    raise err
  File "/home/airflow/.local/lib/python3.12/site-packages/pandas/io/sql.py", line 1498, in insert_records
    return table.insert(chunksize=chunksize, method=method)
           ^^^^^^^^^^^^^^^^^^^^^^^^^^^^^^^^^^^^^^^^^^^^^^^^
  File "/home/airflow/.local/lib/python3.12/site-packages/pandas/io/sql.py", line 1059, in insert
    num_inserted = exec_insert(conn, keys, chunk_iter)
                   ^^^^^^^^^^^^^^^^^^^^^^^^^^^^^^^^^^^
  File "/home/airflow/.local/lib/python3.12/site-packages/pandas/io/sql.py", line 951, in _execute_insert
    result = conn.execute(self.table.insert(), data)
             ^^^^^^^^^^^^^^^^^^^^^^^^^^^^^^^^^^^^^^^
  File "/home/airflow/.local/lib/python3.12/site-packages/sqlalchemy/engine/base.py", line 1385, in execute
    return meth(self, multiparams, params, _EMPTY_EXECUTION_OPTS)
           ^^^^^^^^^^^^^^^^^^^^^^^^^^^^^^^^^^^^^^^^^^^^^^^^^^^^^^
  File "/home/airflow/.local/lib/python3.12/site-packages/sqlalchemy/sql/elements.py", line 334, in _execute_on_connection
    return connection._execute_clauseelement(
           ^^^^^^^^^^^^^^^^^^^^^^^^^^^^^^^^^^
  File "/home/airflow/.local/lib/python3.12/site-packages/sqlalchemy/engine/base.py", line 1577, in _execute_clauseelement
    ret = self._execute_context(
          ^^^^^^^^^^^^^^^^^^^^^^
  File "/home/airflow/.local/lib/python3.12/site-packages/sqlalchemy/engine/base.py", line 1953, in _execute_context
    self._handle_dbapi_exception(
  File "/home/airflow/.local/lib/python3.12/site-packages/sqlalchemy/engine/base.py", line 2134, in _handle_dbapi_exception
    util.raise_(
  File "/home/airflow/.local/lib/python3.12/site-packages/sqlalchemy/util/compat.py", line 211, in raise_
    raise exception
  File "/home/airflow/.local/lib/python3.12/site-packages/sqlalchemy/engine/base.py", line 1890, in _execute_context
    self.dialect.do_executemany(
  File "/home/airflow/.local/lib/python3.12/site-packages/sqlalchemy/dialects/postgresql/psycopg2.py", line 982, in do_executemany
    context._psycopg2_fetched_rows = xtras.execute_values(
                                     ^^^^^^^^^^^^^^^^^^^^^
  File "/home/airflow/.local/lib/python3.12/site-packages/psycopg2/extras.py", line 1299, in execute_values
    cur.execute(b''.join(parts))
sqlalchemy.exc.IntegrityError: (psycopg2.errors.UniqueViolation) duplicate key value violates unique constraint "order_items_pkey"
DETAIL:  Key (order_item_id)=(20001) already exists.

[SQL: INSERT INTO order_items (order_item_id, order_id, product_id, quantity, price_at_purchase, unit_price) VALUES (%(order_item_id)s, %(order_id)s, %(product_id)s, %(quantity)s, %(price_at_purchase)s, %(unit_price)s)]
[parameters: ({'order_item_id': 1, 'order_id': 6550, 'product_id': 1032, 'quantity': 1, 'price_at_purchase': 342.92, 'unit_price': None}, {'order_item_id': 2, 'order_id': 7324, 'product_id': 1695, 'quantity': 1, 'price_at_purchase': 955.86, 'unit_price': None}, {'order_item_id': 3, 'order_id': 11952, 'product_id': 1962, 'quantity': 1, 'price_at_purchase': 909.45, 'unit_price': None}, {'order_item_id': 4, 'order_id': 8938, 'product_id': 1958, 'quantity': 1, 'price_at_purchase': 984.91, 'unit_price': None}, {'order_item_id': 5, 'order_id': 4238, 'product_id': 1880, 'quantity': 1, 'price_at_purchase': 649.18, 'unit_price': None}, {'order_item_id': 6, 'order_id': 14235, 'product_id': 672, 'quantity': 1, 'price_at_purchase': 695.76, 'unit_price': None}, {'order_item_id': 7, 'order_id': 10944, 'product_id': 1, 'quantity': 1, 'price_at_purchase': 54.83, 'unit_price': None}, {'order_item_id': 8, 'order_id': 11075, 'product_id': 827, 'quantity': 1, 'price_at_purchase': 320.24, 'unit_price': None}  ... displaying 10 of 20061 total bound parameter sets ...  {'order_item_id': 20026, 'order_id': 15026, 'product_id': 1200, 'quantity': 5, 'price_at_purchase': None, 'unit_price': 33.02}, {'order_item_id': 20026, 'order_id': 15026, 'product_id': 8, 'quantity': 1, 'price_at_purchase': None, 'unit_price': 378.12})]
(Background on this error at: https://sqlalche.me/e/14/gkpj)
[2025-08-26T13:35:57.245+0000] {taskinstance.py:1206} INFO - Marking task as FAILED. dag_id=import_csv_to_postgres, task_id=load_csv_to_postgres, run_id=manual__2025-08-26T13:35:51.540848+00:00, execution_date=20250826T133551, start_date=20250826T133553, end_date=20250826T133557
[2025-08-26T13:35:57.260+0000] {standard_task_runner.py:110} ERROR - Failed to execute job 615 for task load_csv_to_postgres ((psycopg2.errors.UniqueViolation) duplicate key value violates unique constraint "order_items_pkey"
DETAIL:  Key (order_item_id)=(20001) already exists.

[SQL: INSERT INTO order_items (order_item_id, order_id, product_id, quantity, price_at_purchase, unit_price) VALUES (%(order_item_id)s, %(order_id)s, %(product_id)s, %(quantity)s, %(price_at_purchase)s, %(unit_price)s)]
[parameters: ({'order_item_id': 1, 'order_id': 6550, 'product_id': 1032, 'quantity': 1, 'price_at_purchase': 342.92, 'unit_price': None}, {'order_item_id': 2, 'order_id': 7324, 'product_id': 1695, 'quantity': 1, 'price_at_purchase': 955.86, 'unit_price': None}, {'order_item_id': 3, 'order_id': 11952, 'product_id': 1962, 'quantity': 1, 'price_at_purchase': 909.45, 'unit_price': None}, {'order_item_id': 4, 'order_id': 8938, 'product_id': 1958, 'quantity': 1, 'price_at_purchase': 984.91, 'unit_price': None}, {'order_item_id': 5, 'order_id': 4238, 'product_id': 1880, 'quantity': 1, 'price_at_purchase': 649.18, 'unit_price': None}, {'order_item_id': 6, 'order_id': 14235, 'product_id': 672, 'quantity': 1, 'price_at_purchase': 695.76, 'unit_price': None}, {'order_item_id': 7, 'order_id': 10944, 'product_id': 1, 'quantity': 1, 'price_at_purchase': 54.83, 'unit_price': None}, {'order_item_id': 8, 'order_id': 11075, 'product_id': 827, 'quantity': 1, 'price_at_purchase': 320.24, 'unit_price': None}  ... displaying 10 of 20061 total bound parameter sets ...  {'order_item_id': 20026, 'order_id': 15026, 'product_id': 1200, 'quantity': 5, 'price_at_purchase': None, 'unit_price': 33.02}, {'order_item_id': 20026, 'order_id': 15026, 'product_id': 8, 'quantity': 1, 'price_at_purchase': None, 'unit_price': 378.12})]
(Background on this error at: https://sqlalche.me/e/14/gkpj); 1147)
[2025-08-26T13:35:57.315+0000] {local_task_job_runner.py:243} INFO - Task exited with return code 1
[2025-08-26T13:35:57.354+0000] {taskinstance.py:3503} INFO - 0 downstream tasks scheduled from follow-on schedule check
[2025-08-26T13:35:57.362+0000] {local_task_job_runner.py:222} INFO - ::endgroup::
